Workbook
Name DAFTAR_KATEGORI: KATEGORI_PENGELUARAN!$D$4:$D$10
Name DAFTAR_NAMA: MASTER_ANGGOTA!$B$5:$B$45
Name PENG_BULAN: PENGELUARAN!$N$4:$N$300
Name PENG_JUMLAH: PENGELUARAN!$G$4:$G$300
Name PENG_KATEGORI: PENGELUARAN!$C$4:$C$300
Name SALDO_AKHIR_TAHUN: SALDO!$G$14

Sheet DASHBOARD
A1: DASHBOARD KAS KELAS — TAHUN AJARAN 2026/2027
A2: Update terakhir mengikuti data pada sheet PEMBAYARAN & PENGELUARAN (otomatis).
A4: SALDO KAS SAAT INI | C4: TOTAL PEMASUKAN | E4: TOTAL PENGELUARAN | G4: TOTAL WAJIB KAS | I4: TOTAL KAS TERKUMPUL | K4: TOTAL TUNGGAKAN
A6: =SALDO_AKHIR_TAHUN -> -100000 | C6: =SUM(REKAP_BULANAN!D4:D13) -> 25000 | E6: =SUM(REKAP_BULANAN!F4:F13) -> 125000 | G6: =SUM(REKAP_BULANAN!C4:C13) -> 8610000 | I6: =SUM(REKAP_BULANAN!D4:D13) -> 25000 | K6: =SUM(REKAP_BULANAN!E4:E13) -> 8585000
A14: ANGGOTA SUDAH LUNAS (rata-rata/bln) | E14: ANGGOTA CICILAN (rata-rata/bln) | I14: ANGGOTA BELUM BAYAR (rata-rata/bln)
A16: =ROUND(AVERAGE(REKAP_BULANAN!I4:I13),0) -> 0 | E16: =ROUND(AVERAGE(REKAP_BULANAN!J4:J13),0) -> 0 | I16: =ROUND(AVERAGE(REKAP_BULANAN!K4:K13),0) -> 41
A38: Status | B38: Jumlah Anggota (rata-rata)
A39: LUNAS | B39: =ROUND(AVERAGE(REKAP_BULANAN!I4:I13),0) -> 0
A40: CICILAN | B40: =ROUND(AVERAGE(REKAP_BULANAN!J4:J13),0) -> 0
A41: BELUM BAYAR | B41: =ROUND(AVERAGE(REKAP_BULANAN!K4:K13),0) -> 41

Sheet PANDUAN
A1: PANDUAN PENGGUNAAN WORKBOOK
A3: LANGKAH 1 | B3: Isi 41 nama anggota kelas pada sheet MASTER_ANGGOTA (kolom B, sel kuning).
A4: LANGKAH 2 | B4: Setiap ada pembayaran kas (termasuk cicilan / berkali-kali), tambahkan satu baris baru di sheet PEMBAYARAN.
A5: LANGKAH 3 | B5: Setiap ada pengeluaran, tambahkan satu baris baru di sheet PENGELUARAN.
A6: LANGKAH 4 | B6: Buka sheet KAS_<BULAN> untuk melihat rekap per bulan, DAFTAR_TUNGGAKAN untuk memantau yang belum lunas, dan DASHBOARD untuk ringkasan otomatis.
A7: CATATAN | B7: Jangan mengubah rumus (font hitam/hijau). Sel berwarna kuning dengan font biru adalah sel yang boleh diisi/diedit.
A8: CATATAN | B8: 5 baris contoh transaksi di PEMBAYARAN dan PENGELUARAN adalah data uji coba - boleh dihapus kapan saja tanpa merusak rumus.
A9: CATATAN | B9: Jumlah minggu aktif tiap bulan (sel D2 di setiap sheet KAS_<BULAN>) dapat diubah bendahara sesuai kalender sekolah.

Sheet MASTER_ANGGOTA
A1: DAFTAR ANGGOTA KELAS (MASTER)
A2: Tahun Ajaran: | B2: 2026/2027 | D2: Jumlah Anggota: | E2: =COUNTA(B5:B45) -> 41
A3: Kuning = sel input (boleh diedit) | Putih = hasil formula (otomatis)
A4: No | B4: Nama | C4: Kelas/Keterangan | D4: Status Keanggotaan
A5: 1 | B5: Budi | D5: Aktif
A6: 2 | B6: Andi | D6: Aktif
A7: 3 | B7: Citra | D7: Aktif
A8: 4 | B8: Doni | D8: Aktif
A9: 5 | B9: Nama Siswa 5 | D9: Aktif
A10: 6 | B10: Nama Siswa 6 | D10: Aktif
A11: 7 | B11: Nama Siswa 7 | D11: Aktif
A12: 8 | B12: Nama Siswa 8 | D12: Aktif
A13: 9 | B13: Nama Siswa 9 | D13: Aktif
A14: 10 | B14: Nama Siswa 10 | D14: Aktif
A15: 11 | B15: Nama Siswa 11 | D15: Aktif
A16: 12 | B16: Nama Siswa 12 | D16: Aktif
... A45: 41 | B45: Nama Siswa 41 | D45: Aktif

Sheet KATEGORI_PENGELUARAN
A1: DAFTAR KATEGORI & SUBKATEGORI PENGELUARAN
A2: Edit daftar ini untuk menambah/mengubah kategori. Dropdown pada sheet PENGELUARAN akan mengikuti daftar ini.
A3: Kategori | B3: Subkategori | D3: Daftar Kategori (untuk dropdown)
A4: KEGIATAN KELAS | B4: Acara kelas | D4: KEGIATAN KELAS
B5: Perayaan | D5: PERLENGKAPAN
B6: Lomba | D6: KEBERSIHAN
B7: Study tour | D7: SOSIAL
B8: Kegiatan lainnya | D8: KONSUMSI
A9: PERLENGKAPAN | B9: Alat tulis | D9: ADMINISTRASI
B10: Kertas | D10: LAINNYA
B11: Spidol
B12: Papan tulis
B13: Dekorasi
B14: Perlengkapan kelas
A15: KEBERSIHAN | B15: Sapu
B16: Pel
B17: Tisu
B18: Sabun
B19: Tempat sampah
B20: Peralatan kebersihan
A21: SOSIAL | B21: Sumbangan
B22: Takziah
B23: Bantuan anggota
B24: Kegiatan sosial
A25: KONSUMSI | B25: Air minum
B26: Makanan
B27: Snack
B28: Konsumsi kegiatan
A29: ADMINISTRASI | B29: Fotokopi
B30: Print
B31: Materai
B32: Administrasi lainnya
A33: LAINNYA | B33: Pengeluaran tidak terduga
B34: Pengeluaran lainnya

Sheet PEMBAYARAN
A1: CATATAN PEMBAYARAN KAS (SEMUA TRANSAKSI)
A2: Setiap kali anggota membayar (walau dicicil / berkali-kali), tambahkan SATU baris baru di sini. Jangan menimpa baris lama.
A3: Nama | B3: Bulan | C3: Minggu | D3: Tanggal | E3: Nominal Pembayaran | F3: Metode | G3: Keterangan | I3: Cek: Nama Tidak Terdaftar?
A4: Andi | B4: September | C4: Minggu 1 | D4: 46269 | E4: 5000 | F4: Tunai | G4: Pelunasan langsung | I4: =IF($A4="","",IF(COUNTIF(DAFTAR_NAMA,$A4)=0,"⚠️ NAMA TIDAK TERDAFTAR","OK")) -> OK
A5: Budi | B5: September | C5: Minggu 1 | D5: 46269 | E5: 2000 | F5: Tunai | G5: Cicilan 1 | I5: =IF($A5="","",IF(COUNTIF(DAFTAR_NAMA,$A5)=0,"⚠️ NAMA TIDAK TERDAFTAR","OK")) -> OK
A6: Budi | B6: September | C6: Minggu 1 | D6: 46270 | E6: 1000 | F6: Tunai | G6: Cicilan 2 | I6: =IF($A6="","",IF(COUNTIF(DAFTAR_NAMA,$A6)=0,"⚠️ NAMA TIDAK TERDAFTAR","OK")) -> OK
A7: Budi | B7: September | C7: Minggu 1 | D7: 46271 | E7: 2000 | F7: Tunai | G7: Pelunasan | I7: =IF($A7="","",IF(COUNTIF(DAFTAR_NAMA,$A7)=0,"⚠️ NAMA TIDAK TERDAFTAR","OK")) -> OK
A8: Doni | B8: September | C8: Minggu 1 | D8: 46269 | E8: 7000 | F8: Transfer | G8: Lebih Rp2.000 (kelebihan) | I8: =IF($A8="","",IF(COUNTIF(DAFTAR_NAMA,$A8)=0,"⚠️ NAMA TIDAK TERDAFTAR","OK")) -> OK
A9: Andi | B9: September | C9: Minggu 2 | D9: 46276 | E9: 5000 | F9: Tunai | G9: Lunas | I9: =IF($A9="","",IF(COUNTIF(DAFTAR_NAMA,$A9)=0,"⚠️ NAMA TIDAK TERDAFTAR","OK")) -> OK
A10: Budi | B10: September | C10: Minggu 2 | D10: 46277 | E10: 3000 | F10: Tunai | G10: Cicilan, kurang Rp2.000 | I10: =IF($A10="","",IF(COUNTIF(DAFTAR_NAMA,$A10)=0,"⚠️ NAMA TIDAK TERDAFTAR","OK")) -> OK
I11: =IF($A11="","",IF(COUNTIF(DAFTAR_NAMA,$A11)=0,"⚠️ NAMA TIDAK TERDAFTAR","OK"))
I12: =IF($A12="","",IF(COUNTIF(DAFTAR_NAMA,$A12)=0,"⚠️ NAMA TIDAK TERDAFTAR","OK"))
I13: =IF($A13="","",IF(COUNTIF(DAFTAR_NAMA,$A13)=0,"⚠️ NAMA TIDAK TERDAFTAR","OK"))
I14: =IF($A14="","",IF(COUNTIF(DAFTAR_NAMA,$A14)=0,"⚠️ NAMA TIDAK TERDAFTAR","OK"))
I15: =IF($A15="","",IF(COUNTIF(DAFTAR_NAMA,$A15)=0,"⚠️ NAMA TIDAK TERDAFTAR","OK"))
I16: =IF($A16="","",IF(COUNTIF(DAFTAR_NAMA,$A16)=0,"⚠️ NAMA TIDAK TERDAFTAR","OK"))
I17: =IF($A17="","",IF(COUNTIF(DAFTAR_NAMA,$A17)=0,"⚠️ NAMA TIDAK TERDAFTAR","OK"))
I18: =IF($A18="","",IF(COUNTIF(DAFTAR_NAMA,$A18)=0,"⚠️ NAMA TIDAK TERDAFTAR","OK"))
I19: =IF($A19="","",IF(COUNTIF(DAFTAR_NAMA,$A19)=0,"⚠️ NAMA TIDAK TERDAFTAR","OK"))
I20: =IF($A20="","",IF(COUNTIF(DAFTAR_NAMA,$A20)=0,"⚠️ NAMA TIDAK TERDAFTAR","OK"))
I21: =IF($A21="","",IF(COUNTIF(DAFTAR_NAMA,$A21)=0,"⚠️ NAMA TIDAK TERDAFTAR","OK"))
I22: =IF($A22="","",IF(COUNTIF(DAFTAR_NAMA,$A22)=0,"⚠️ NAMA TIDAK TERDAFTAR","OK"))
... I500: =IF($A500="","",IF(COUNTIF(DAFTAR_NAMA,$A500)=0,"⚠️ NAMA TIDAK TERDAFTAR","OK"))

Sheet KAS_SEPTEMBER
A1: REKAP KAS BULAN SEPTEMBER 2026/2027
A2: Jumlah Minggu Aktif Bulan Ini: | D2: 4 | E2: Iuran / Minggu: | F2: 5000
A3: Kuning = sel input (boleh diedit) | Putih = hasil formula (otomatis)
A4: No | B4: Nama | C4: Minggu 1 | D4: Minggu 2 | E4: Minggu 3 | F4: Minggu 4 | G4: Minggu 5 | H4: Total Wajib | I4: Total Dibayar | J4: Kekurangan | K4: Kelebihan | L4: Status | M4: Status M1 | N4: Status M2 | O4: Status M3 | P4: Status M4 | Q4: Status M5
A5: =MASTER_ANGGOTA!A5 -> 1 | B5: =MASTER_ANGGOTA!B5 -> Budi | C5: =IF(1<=$D$2,SUMIFS(PEMBAYARAN!$E$4:$E$500,PEMBAYARAN!$A$4:$A$500,$B5,PEMBAYARAN!$B$4:$B$500,"September",PEMBAYARAN!$C$4:$C$500,"Minggu 1"),"") -> 5000 | D5: =IF(2<=$D$2,SUMIFS(PEMBAYARAN!$E$4:$E$500,PEMBAYARAN!$A$4:$A$500,$B5,PEMBAYARAN!$B$4:$B$500,"September",PEMBAYARAN!$C$4:$C$500,"Minggu 2"),"") -> 3000 | E5: =IF(3<=$D$2,SUMIFS(PEMBAYARAN!$E$4:$E$500,PEMBAYARAN!$A$4:$A$500,$B5,PEMBAYARAN!$B$4:$B$500,"September",PEMBAYARAN!$C$4:$C$500,"Minggu 3"),"") -> 0 | F5: =IF(4<=$D$2,SUMIFS(PEMBAYARAN!$E$4:$E$500,PEMBAYARAN!$A$4:$A$500,$B5,PEMBAYARAN!$B$4:$B$500,"September",PEMBAYARAN!$C$4:$C$500,"Minggu 4"),"") -> 0 | G5: =IF(5<=$D$2,SUMIFS(PEMBAYARAN!$E$4:$E$500,PEMBAYARAN!$A$4:$A$500,$B5,PEMBAYARAN!$B$4:$B$500,"September",PEMBAYARAN!$C$4:$C$500,"Minggu 5"),"") | H5: =MIN($D$2,5)*$F$2 -> 20000 | I5: =SUM(C5:G5) -> 8000 | J5: =MAX(H5-I5,0) -> 12000 | K5: =MAX(I5-H5,0) -> 0 | L5: =IF(I5=0,"BELUM BAYAR",IF(I5<H5,"CICILAN",IF(I5>H5,"LUNAS (LEBIH)","LUNAS"))) -> CICILAN | M5: =IF(C5="","-",IF(C5=0,"BELUM BAYAR",IF(C5<$F$2,"CICILAN",IF(C5>$F$2,"LUNAS (LEBIH)","LUNAS")))) -> LUNAS | N5: =IF(D5="","-",IF(D5=0,"BELUM BAYAR",IF(D5<$F$2,"CICILAN",IF(D5>$F$2,"LUNAS (LEBIH)","LUNAS")))) -> CICILAN | O5: =IF(E5="","-",IF(E5=0,"BELUM BAYAR",IF(E5<$F$2,"CICILAN",IF(E5>$F$2,"LUNAS (LEBIH)","LUNAS")))) -> BELUM BAYAR | P5: =IF(F5="","-",IF(F5=0,"BELUM BAYAR",IF(F5<$F$2,"CICILAN",IF(F5>$F$2,"LUNAS (LEBIH)","LUNAS")))) -> BELUM BAYAR | Q5: =IF(G5="","-",IF(G5=0,"BELUM BAYAR",IF(G5<$F$2,"CICILAN",IF(G5>$F$2,"LUNAS (LEBIH)","LUNAS")))) -> -
A6: =MASTER_ANGGOTA!A6 -> 2 | B6: =MASTER_ANGGOTA!B6 -> Andi | C6: =IF(1<=$D$2,SUMIFS(PEMBAYARAN!$E$4:$E$500,PEMBAYARAN!$A$4:$A$500,$B6,PEMBAYARAN!$B$4:$B$500,"September",PEMBAYARAN!$C$4:$C$500,"Minggu 1"),"") -> 5000 | D6: =IF(2<=$D$2,SUMIFS(PEMBAYARAN!$E$4:$E$500,PEMBAYARAN!$A$4:$A$500,$B6,PEMBAYARAN!$B$4:$B$500,"September",PEMBAYARAN!$C$4:$C$500,"Minggu 2"),"") -> 5000 | E6: =IF(3<=$D$2,SUMIFS(PEMBAYARAN!$E$4:$E$500,PEMBAYARAN!$A$4:$A$500,$B6,PEMBAYARAN!$B$4:$B$500,"September",PEMBAYARAN!$C$4:$C$500,"Minggu 3"),"") -> 0 | F6: =IF(4<=$D$2,SUMIFS(PEMBAYARAN!$E$4:$E$500,PEMBAYARAN!$A$4:$A$500,$B6,PEMBAYARAN!$B$4:$B$500,"September",PEMBAYARAN!$C$4:$C$500,"Minggu 4"),"") -> 0 | G6: =IF(5<=$D$2,SUMIFS(PEMBAYARAN!$E$4:$E$500,PEMBAYARAN!$A$4:$A$500,$B6,PEMBAYARAN!$B$4:$B$500,"September",PEMBAYARAN!$C$4:$C$500,"Minggu 5"),"") | H6: =MIN($D$2,5)*$F$2 -> 20000 | I6: =SUM(C6:G6) -> 10000 | J6: =MAX(H6-I6,0) -> 10000 | K6: =MAX(I6-H6,0) -> 0 | L6: =IF(I6=0,"BELUM BAYAR",IF(I6<H6,"CICILAN",IF(I6>H6,"LUNAS (LEBIH)","LUNAS"))) -> CICILAN | M6: =IF(C6="","-",IF(C6=0,"BELUM BAYAR",IF(C6<$F$2,"CICILAN",IF(C6>$F$2,"LUNAS (LEBIH)","LUNAS")))) -> LUNAS | N6: =IF(D6="","-",IF(D6=0,"BELUM BAYAR",IF(D6<$F$2,"CICILAN",IF(D6>$F$2,"LUNAS (LEBIH)","LUNAS")))) -> LUNAS | O6: =IF(E6="","-",IF(E6=0,"BELUM BAYAR",IF(E6<$F$2,"CICILAN",IF(E6>$F$2,"LUNAS (LEBIH)","LUNAS")))) -> BELUM BAYAR | P6: =IF(F6="","-",IF(F6=0,"BELUM BAYAR",IF(F6<$F$2,"CICILAN",IF(F6>$F$2,"LUNAS (LEBIH)","LUNAS")))) -> BELUM BAYAR | Q6: =IF(G6="","-",IF(G6=0,"BELUM BAYAR",IF(G6<$F$2,"CICILAN",IF(G6>$F$2,"LUNAS (LEBIH)","LUNAS")))) -> -
A7: =MASTER_ANGGOTA!A7 -> 3 | B7: =MASTER_ANGGOTA!B7 -> Citra | C7: =IF(1<=$D$2,SUMIFS(PEMBAYARAN!$E$4:$E$500,PEMBAYARAN!$A$4:$A$500,$B7,PEMBAYARAN!$B$4:$B$500,"September",PEMBAYARAN!$C$4:$C$500,"Minggu 1"),"") -> 0 | D7: =IF(2<=$D$2,SUMIFS(PEMBAYARAN!$E$4:$E$500,PEMBAYARAN!$A$4:$A$500,$B7,PEMBAYARAN!$B$4:$B$500,"September",PEMBAYARAN!$C$4:$C$500,"Minggu 2"),"") -> 0 | E7: =IF(3<=$D$2,SUMIFS(PEMBAYARAN!$E$4:$E$500,PEMBAYARAN!$A$4:$A$500,$B7,PEMBAYARAN!$B$4:$B$500,"September",PEMBAYARAN!$C$4:$C$500,"Minggu 3"),"") -> 0 | F7: =IF(4<=$D$2,SUMIFS(PEMBAYARAN!$E$4:$E$500,PEMBAYARAN!$A$4:$A$500,$B7,PEMBAYARAN!$B$4:$B$500,"September",PEMBAYARAN!$C$4:$C$500,"Minggu 4"),"") -> 0 | G7: =IF(5<=$D$2,SUMIFS(PEMBAYARAN!$E$4:$E$500,PEMBAYARAN!$A$4:$A$500,$B7,PEMBAYARAN!$B$4:$B$500,"September",PEMBAYARAN!$C$4:$C$500,"Minggu 5"),"") | H7: =MIN($D$2,5)*$F$2 -> 20000 | I7: =SUM(C7:G7) -> 0 | J7: =MAX(H7-I7,0) -> 20000 | K7: =MAX(I7-H7,0) -> 0 | L7: =IF(I7=0,"BELUM BAYAR",IF(I7<H7,"CICILAN",IF(I7>H7,"LUNAS (LEBIH)","LUNAS"))) -> BELUM BAYAR | M7: =IF(C7="","-",IF(C7=0,"BELUM BAYAR",IF(C7<$F$2,"CICILAN",IF(C7>$F$2,"LUNAS (LEBIH)","LUNAS")))) -> BELUM BAYAR | N7: =IF(D7="","-",IF(D7=0,"BELUM BAYAR",IF(D7<$F$2,"CICILAN",IF(D7>$F$2,"LUNAS (LEBIH)","LUNAS")))) -> BELUM BAYAR | O7: =IF(E7="","-",IF(E7=0,"BELUM BAYAR",IF(E7<$F$2,"CICILAN",IF(E7>$F$2,"LUNAS (LEBIH)","LUNAS")))) -> BELUM BAYAR | P7: =IF(F7="","-",IF(F7=0,"BELUM BAYAR",IF(F7<$F$2,"CICILAN",IF(F7>$F$2,"LUNAS (LEBIH)","LUNAS")))) -> BELUM BAYAR | Q7: =IF(G7="","-",IF(G7=0,"BELUM BAYAR",IF(G7<$F$2,"CICILAN",IF(G7>$F$2,"LUNAS (LEBIH)","LUNAS")))) -> -
A8: =MASTER_ANGGOTA!A8 -> 4 | B8: =MASTER_ANGGOTA!B8 -> Doni | C8: =IF(1<=$D$2,SUMIFS(PEMBAYARAN!$E$4:$E$500,PEMBAYARAN!$A$4:$A$500,$B8,PEMBAYARAN!$B$4:$B$500,"September",PEMBAYARAN!$C$4:$C$500,"Minggu 1"),"") -> 7000 | D8: =IF(2<=$D$2,SUMIFS(PEMBAYARAN!$E$4:$E$500,PEMBAYARAN!$A$4:$A$500,$B8,PEMBAYARAN!$B$4:$B$500,"September",PEMBAYARAN!$C$4:$C$500,"Minggu 2"),"") -> 0 | E8: =IF(3<=$D$2,SUMIFS(PEMBAYARAN!$E$4:$E$500,PEMBAYARAN!$A$4:$A$500,$B8,PEMBAYARAN!$B$4:$B$500,"September",PEMBAYARAN!$C$4:$C$500,"Minggu 3"),"") -> 0 | F8: =IF(4<=$D$2,SUMIFS(PEMBAYARAN!$E$4:$E$500,PEMBAYARAN!$A$4:$A$500,$B8,PEMBAYARAN!$B$4:$B$500,"September",PEMBAYARAN!$C$4:$C$500,"Minggu 4"),"") -> 0 | G8: =IF(5<=$D$2,SUMIFS(PEMBAYARAN!$E$4:$E$500,PEMBAYARAN!$A$4:$A$500,$B8,PEMBAYARAN!$B$4:$B$500,"September",PEMBAYARAN!$C$4:$C$500,"Minggu 5"),"") | H8: =MIN($D$2,5)*$F$2 -> 20000 | I8: =SUM(C8:G8) -> 7000 | J8: =MAX(H8-I8,0) -> 13000 | K8: =MAX(I8-H8,0) -> 0 | L8: =IF(I8=0,"BELUM BAYAR",IF(I8<H8,"CICILAN",IF(I8>H8,"LUNAS (LEBIH)","LUNAS"))) -> CICILAN | M8: =IF(C8="","-",IF(C8=0,"BELUM BAYAR",IF(C8<$F$2,"CICILAN",IF(C8>$F$2,"LUNAS (LEBIH)","LUNAS")))) -> LUNAS (LEBIH) | N8: =IF(D8="","-",IF(D8=0,"BELUM BAYAR",IF(D8<$F$2,"CICILAN",IF(D8>$F$2,"LUNAS (LEBIH)","LUNAS")))) -> BELUM BAYAR | O8: =IF(E8="","-",IF(E8=0,"BELUM BAYAR",IF(E8<$F$2,"CICILAN",IF(E8>$F$2,"LUNAS (LEBIH)","LUNAS")))) -> BELUM BAYAR | P8: =IF(F8="","-",IF(F8=0,"BELUM BAYAR",IF(F8<$F$2,"CICILAN",IF(F8>$F$2,"LUNAS (LEBIH)","LUNAS")))) -> BELUM BAYAR | Q8: =IF(G8="","-",IF(G8=0,"BELUM BAYAR",IF(G8<$F$2,"CICILAN",IF(G8>$F$2,"LUNAS (LEBIH)","LUNAS")))) -> -
A9: =MASTER_ANGGOTA!A9 -> 5 | B9: =MASTER_ANGGOTA!B9 -> Nama Siswa 5 | C9: =IF(1<=$D$2,SUMIFS(PEMBAYARAN!$E$4:$E$500,PEMBAYARAN!$A$4:$A$500,$B9,PEMBAYARAN!$B$4:$B$500,"September",PEMBAYARAN!$C$4:$C$500,"Minggu 1"),"") -> 0 | D9: =IF(2<=$D$2,SUMIFS(PEMBAYARAN!$E$4:$E$500,PEMBAYARAN!$A$4:$A$500,$B9,PEMBAYARAN!$B$4:$B$500,"September",PEMBAYARAN!$C$4:$C$500,"Minggu 2"),"") -> 0 | E9: =IF(3<=$D$2,SUMIFS(PEMBAYARAN!$E$4:$E$500,PEMBAYARAN!$A$4:$A$500,$B9,PEMBAYARAN!$B$4:$B$500,"September",PEMBAYARAN!$C$4:$C$500,"Minggu 3"),"") -> 0 | F9: =IF(4<=$D$2,SUMIFS(PEMBAYARAN!$E$4:$E$500,PEMBAYARAN!$A$4:$A$500,$B9,PEMBAYARAN!$B$4:$B$500,"September",PEMBAYARAN!$C$4:$C$500,"Minggu 4"),"") -> 0 | G9: =IF(5<=$D$2,SUMIFS(PEMBAYARAN!$E$4:$E$500,PEMBAYARAN!$A$4:$A$500,$B9,PEMBAYARAN!$B$4:$B$500,"September",PEMBAYARAN!$C$4:$C$500,"Minggu 5"),"") | H9: =MIN($D$2,5)*$F$2 -> 20000 | I9: =SUM(C9:G9) -> 0 | J9: =MAX(H9-I9,0) -> 20000 | K9: =MAX(I9-H9,0) -> 0 | L9: =IF(I9=0,"BELUM BAYAR",IF(I9<H9,"CICILAN",IF(I9>H9,"LUNAS (LEBIH)","LUNAS"))) -> BELUM BAYAR | M9: =IF(C9="","-",IF(C9=0,"BELUM BAYAR",IF(C9<$F$2,"CICILAN",IF(C9>$F$2,"LUNAS (LEBIH)","LUNAS")))) -> BELUM BAYAR | N9: =IF(D9="","-",IF(D9=0,"BELUM BAYAR",IF(D9<$F$2,"CICILAN",IF(D9>$F$2,"LUNAS (LEBIH)","LUNAS")))) -> BELUM BAYAR | O9: =IF(E9="","-",IF(E9=0,"BELUM BAYAR",IF(E9<$F$2,"CICILAN",IF(E9>$F$2,"LUNAS (LEBIH)","LUNAS")))) -> BELUM BAYAR | P9: =IF(F9="","-",IF(F9=0,"BELUM BAYAR",IF(F9<$F$2,"CICILAN",IF(F9>$F$2,"LUNAS (LEBIH)","LUNAS")))) -> BELUM BAYAR | Q9: =IF(G9="","-",IF(G9=0,"BELUM BAYAR",IF(G9<$F$2,"CICILAN",IF(G9>$F$2,"LUNAS (LEBIH)","LUNAS")))) -> -
A10: =MASTER_ANGGOTA!A10 -> 6 | B10: =MASTER_ANGGOTA!B10 -> Nama Siswa 6 | C10: =IF(1<=$D$2,SUMIFS(PEMBAYARAN!$E$4:$E$500,PEMBAYARAN!$A$4:$A$500,$B10,PEMBAYARAN!$B$4:$B$500,"September",PEMBAYARAN!$C$4:$C$500,"Minggu 1"),"") -> 0 | D10: =IF(2<=$D$2,SUMIFS(PEMBAYARAN!$E$4:$E$500,PEMBAYARAN!$A$4:$A$500,$B10,PEMBAYARAN!$B$4:$B$500,"September",PEMBAYARAN!$C$4:$C$500,"Minggu 2"),"") -> 0 | E10: =IF(3<=$D$2,SUMIFS(PEMBAYARAN!$E$4:$E$500,PEMBAYARAN!$A$4:$A$500,$B10,PEMBAYARAN!$B$4:$B$500,"September",PEMBAYARAN!$C$4:$C$500,"Minggu 3"),"") -> 0 | F10: =IF(4<=$D$2,SUMIFS(PEMBAYARAN!$E$4:$E$500,PEMBAYARAN!$A$4:$A$500,$B10,PEMBAYARAN!$B$4:$B$500,"September",PEMBAYARAN!$C$4:$C$500,"Minggu 4"),"") -> 0 | G10: =IF(5<=$D$2,SUMIFS(PEMBAYARAN!$E$4:$E$500,PEMBAYARAN!$A$4:$A$500,$B10,PEMBAYARAN!$B$4:$B$500,"September",PEMBAYARAN!$C$4:$C$500,"Minggu 5"),"") | H10: =MIN($D$2,5)*$F$2 -> 20000 | I10: =SUM(C10:G10) -> 0 | J10: =MAX(H10-I10,0) -> 20000 | K10: =MAX(I10-H10,0) -> 0 | L10: =IF(I10=0,"BELUM BAYAR",IF(I10<H10,"CICILAN",IF(I10>H10,"LUNAS (LEBIH)","LUNAS"))) -> BELUM BAYAR | M10: =IF(C10="","-",IF(C10=0,"BELUM BAYAR",IF(C10<$F$2,"CICILAN",IF(C10>$F$2,"LUNAS (LEBIH)","LUNAS")))) -> BELUM BAYAR | N10: =IF(D10="","-",IF(D10=0,"BELUM BAYAR",IF(D10<$F$2,"CICILAN",IF(D10>$F$2,"LUNAS (LEBIH)","LUNAS")))) -> BELUM BAYAR | O10: =IF(E10="","-",IF(E10=0,"BELUM BAYAR",IF(E10<$F$2,"CICILAN",IF(E10>$F$2,"LUNAS (LEBIH)","LUNAS")))) -> BELUM BAYAR | P10: =IF(F10="","-",IF(F10=0,"BELUM BAYAR",IF(F10<$F$2,"CICILAN",IF(F10>$F$2,"LUNAS (LEBIH)","LUNAS")))) -> BELUM BAYAR | Q10: =IF(G10="","-",IF(G10=0,"BELUM BAYAR",IF(G10<$F$2,"CICILAN",IF(G10>$F$2,"LUNAS (LEBIH)","LUNAS")))) -> -
A11: =MASTER_ANGGOTA!A11 -> 7 | B11: =MASTER_ANGGOTA!B11 -> Nama Siswa 7 | C11: =IF(1<=$D$2,SUMIFS(PEMBAYARAN!$E$4:$E$500,PEMBAYARAN!$A$4:$A$500,$B11,PEMBAYARAN!$B$4:$B$500,"September",PEMBAYARAN!$C$4:$C$500,"Minggu 1"),"") -> 0 | D11: =IF(2<=$D$2,SUMIFS(PEMBAYARAN!$E$4:$E$500,PEMBAYARAN!$A$4:$A$500,$B11,PEMBAYARAN!$B$4:$B$500,"September",PEMBAYARAN!$C$4:$C$500,"Minggu 2"),"") -> 0 | E11: =IF(3<=$D$2,SUMIFS(PEMBAYARAN!$E$4:$E$500,PEMBAYARAN!$A$4:$A$500,$B11,PEMBAYARAN!$B$4:$B$500,"September",PEMBAYARAN!$C$4:$C$500,"Minggu 3"),"") -> 0 | F11: =IF(4<=$D$2,SUMIFS(PEMBAYARAN!$E$4:$E$500,PEMBAYARAN!$A$4:$A$500,$B11,PEMBAYARAN!$B$4:$B$500,"September",PEMBAYARAN!$C$4:$C$500,"Minggu 4"),"") -> 0 | G11: =IF(5<=$D$2,SUMIFS(PEMBAYARAN!$E$4:$E$500,PEMBAYARAN!$A$4:$A$500,$B11,PEMBAYARAN!$B$4:$B$500,"September",PEMBAYARAN!$C$4:$C$500,"Minggu 5"),"") | H11: =MIN($D$2,5)*$F$2 -> 20000 | I11: =SUM(C11:G11) -> 0 | J11: =MAX(H11-I11,0) -> 20000 | K11: =MAX(I11-H11,0) -> 0 | L11: =IF(I11=0,"BELUM BAYAR",IF(I11<H11,"CICILAN",IF(I11>H11,"LUNAS (LEBIH)","LUNAS"))) -> BELUM BAYAR | M11: =IF(C11="","-",IF(C11=0,"BELUM BAYAR",IF(C11<$F$2,"CICILAN",IF(C11>$F$2,"LUNAS (LEBIH)","LUNAS")))) -> BELUM BAYAR | N11: =IF(D11="","-",IF(D11=0,"BELUM BAYAR",IF(D11<$F$2,"CICILAN",IF(D11>$F$2,"LUNAS (LEBIH)","LUNAS")))) -> BELUM BAYAR | O11: =IF(E11="","-",IF(E11=0,"BELUM BAYAR",IF(E11<$F$2,"CICILAN",IF(E11>$F$2,"LUNAS (LEBIH)","LUNAS")))) -> BELUM BAYAR | P11: =IF(F11="","-",IF(F11=0,"BELUM BAYAR",IF(F11<$F$2,"CICILAN",IF(F11>$F$2,"LUNAS (LEBIH)","LUNAS")))) -> BELUM BAYAR | Q11: =IF(G11="","-",IF(G11=0,"BELUM BAYAR",IF(G11<$F$2,"CICILAN",IF(G11>$F$2,"LUNAS (LEBIH)","LUNAS")))) -> -
A12: =MASTER_ANGGOTA!A12 -> 8 | B12: =MASTER_ANGGOTA!B12 -> Nama Siswa 8 | C12: =IF(1<=$D$2,SUMIFS(PEMBAYARAN!$E$4:$E$500,PEMBAYARAN!$A$4:$A$500,$B12,PEMBAYARAN!$B$4:$B$500,"September",PEMBAYARAN!$C$4:$C$500,"Minggu 1"),"") -> 0 | D12: =IF(2<=$D$2,SUMIFS(PEMBAYARAN!$E$4:$E$500,PEMBAYARAN!$A$4:$A$500,$B12,PEMBAYARAN!$B$4:$B$500,"September",PEMBAYARAN!$C$4:$C$500,"Minggu 2"),"") -> 0 | E12: =IF(3<=$D$2,SUMIFS(PEMBAYARAN!$E$4:$E$500,PEMBAYARAN!$A$4:$A$500,$B12,PEMBAYARAN!$B$4:$B$500,"September",PEMBAYARAN!$C$4:$C$500,"Minggu 3"),"") -> 0 | F12: =IF(4<=$D$2,SUMIFS(PEMBAYARAN!$E$4:$E$500,PEMBAYARAN!$A$4:$A$500,$B12,PEMBAYARAN!$B$4:$B$500,"September",PEMBAYARAN!$C$4:$C$500,"Minggu 4"),"") -> 0 | G12: =IF(5<=$D$2,SUMIFS(PEMBAYARAN!$E$4:$E$500,PEMBAYARAN!$A$4:$A$500,$B12,PEMBAYARAN!$B$4:$B$500,"September",PEMBAYARAN!$C$4:$C$500,"Minggu 5"),"") | H12: =MIN($D$2,5)*$F$2 -> 20000 | I12: =SUM(C12:G12) -> 0 | J12: =MAX(H12-I12,0) -> 20000 | K12: =MAX(I12-H12,0) -> 0 | L12: =IF(I12=0,"BELUM BAYAR",IF(I12<H12,"CICILAN",IF(I12>H12,"LUNAS (LEBIH)","LUNAS"))) -> BELUM BAYAR | M12: =IF(C12="","-",IF(C12=0,"BELUM BAYAR",IF(C12<$F$2,"CICILAN",IF(C12>$F$2,"LUNAS (LEBIH)","LUNAS")))) -> BELUM BAYAR | N12: =IF(D12="","-",IF(D12=0,"BELUM BAYAR",IF(D12<$F$2,"CICILAN",IF(D12>$F$2,"LUNAS (LEBIH)","LUNAS")))) -> BELUM BAYAR | O12: =IF(E12="","-",IF(E12=0,"BELUM BAYAR",IF(E12<$F$2,"CICILAN",IF(E12>$F$2,"LUNAS (LEBIH)","LUNAS")))) -> BELUM BAYAR | P12: =IF(F12="","-",IF(F12=0,"BELUM BAYAR",IF(F12<$F$2,"CICILAN",IF(F12>$F$2,"LUNAS (LEBIH)","LUNAS")))) -> BELUM BAYAR | Q12: =IF(G12="","-",IF(G12=0,"BELUM BAYAR",IF(G12<$F$2,"CICILAN",IF(G12>$F$2,"LUNAS (LEBIH)","LUNAS")))) -> -
A13: =MASTER_ANGGOTA!A13 -> 9 | B13: =MASTER_ANGGOTA!B13 -> Nama Siswa 9 | C13: =IF(1<=$D$2,SUMIFS(PEMBAYARAN!$E$4:$E$500,PEMBAYARAN!$A$4:$A$500,$B13,PEMBAYARAN!$B$4:$B$500,"September",PEMBAYARAN!$C$4:$C$500,"Minggu 1"),"") -> 0 | D13: =IF(2<=$D$2,SUMIFS(PEMBAYARAN!$E$4:$E$500,PEMBAYARAN!$A$4:$A$500,$B13,PEMBAYARAN!$B$4:$B$500,"September",PEMBAYARAN!$C$4:$C$500,"Minggu 2"),"") -> 0 | E13: =IF(3<=$D$2,SUMIFS(PEMBAYARAN!$E$4:$E$500,PEMBAYARAN!$A$4:$A$500,$B13,PEMBAYARAN!$B$4:$B$500,"September",PEMBAYARAN!$C$4:$C$500,"Minggu 3"),"") -> 0 | F13: =IF(4<=$D$2,SUMIFS(PEMBAYARAN!$E$4:$E$500,PEMBAYARAN!$A$4:$A$500,$B13,PEMBAYARAN!$B$4:$B$500,"September",PEMBAYARAN!$C$4:$C$500,"Minggu 4"),"") -> 0 | G13: =IF(5<=$D$2,SUMIFS(PEMBAYARAN!$E$4:$E$500,PEMBAYARAN!$A$4:$A$500,$B13,PEMBAYARAN!$B$4:$B$500,"September",PEMBAYARAN!$C$4:$C$500,"Minggu 5"),"") | H13: =MIN($D$2,5)*$F$2 -> 20000 | I13: =SUM(C13:G13) -> 0 | J13: =MAX(H13-I13,0) -> 20000 | K13: =MAX(I13-H13,0) -> 0 | L13: =IF(I13=0,"BELUM BAYAR",IF(I13<H13,"CICILAN",IF(I13>H13,"LUNAS (LEBIH)","LUNAS"))) -> BELUM BAYAR | M13: =IF(C13="","-",IF(C13=0,"BELUM BAYAR",IF(C13<$F$2,"CICILAN",IF(C13>$F$2,"LUNAS (LEBIH)","LUNAS")))) -> BELUM BAYAR | N13: =IF(D13="","-",IF(D13=0,"BELUM BAYAR",IF(D13<$F$2,"CICILAN",IF(D13>$F$2,"LUNAS (LEBIH)","LUNAS")))) -> BELUM BAYAR | O13: =IF(E13="","-",IF(E13=0,"BELUM BAYAR",IF(E13<$F$2,"CICILAN",IF(E13>$F$2,"LUNAS (LEBIH)","LUNAS")))) -> BELUM BAYAR | P13: =IF(F13="","-",IF(F13=0,"BELUM BAYAR",IF(F13<$F$2,"CICILAN",IF(F13>$F$2,"LUNAS (LEBIH)","LUNAS")))) -> BELUM BAYAR | Q13: =IF(G13="","-",IF(G13=0,"BELUM BAYAR",IF(G13<$F$2,"CICILAN",IF(G13>$F$2,"LUNAS (LEBIH)","LUNAS")))) -> -
A14: =MASTER_ANGGOTA!A14 -> 10 | B14: =MASTER_ANGGOTA!B14 -> Nama Siswa 10 | C14: =IF(1<=$D$2,SUMIFS(PEMBAYARAN!$E$4:$E$500,PEMBAYARAN!$A$4:$A$500,$B14,PEMBAYARAN!$B$4:$B$500,"September",PEMBAYARAN!$C$4:$C$500,"Minggu 1"),"") -> 0 | D14: =IF(2<=$D$2,SUMIFS(PEMBAYARAN!$E$4:$E$500,PEMBAYARAN!$A$4:$A$500,$B14,PEMBAYARAN!$B$4:$B$500,"September",PEMBAYARAN!$C$4:$C$500,"Minggu 2"),"") -> 0 | E14: =IF(3<=$D$2,SUMIFS(PEMBAYARAN!$E$4:$E$500,PEMBAYARAN!$A$4:$A$500,$B14,PEMBAYARAN!$B$4:$B$500,"September",PEMBAYARAN!$C$4:$C$500,"Minggu 3"),"") -> 0 | F14: =IF(4<=$D$2,SUMIFS(PEMBAYARAN!$E$4:$E$500,PEMBAYARAN!$A$4:$A$500,$B14,PEMBAYARAN!$B$4:$B$500,"September",PEMBAYARAN!$C$4:$C$500,"Minggu 4"),"") -> 0 | G14: =IF(5<=$D$2,SUMIFS(PEMBAYARAN!$E$4:$E$500,PEMBAYARAN!$A$4:$A$500,$B14,PEMBAYARAN!$B$4:$B$500,"September",PEMBAYARAN!$C$4:$C$500,"Minggu 5"),"") | H14: =MIN($D$2,5)*$F$2 -> 20000 | I14: =SUM(C14:G14) -> 0 | J14: =MAX(H14-I14,0) -> 20000 | K14: =MAX(I14-H14,0) -> 0 | L14: =IF(I14=0,"BELUM BAYAR",IF(I14<H14,"CICILAN",IF(I14>H14,"LUNAS (LEBIH)","LUNAS"))) -> BELUM BAYAR | M14: =IF(C14="","-",IF(C14=0,"BELUM BAYAR",IF(C14<$F$2,"CICILAN",IF(C14>$F$2,"LUNAS (LEBIH)","LUNAS")))) -> BELUM BAYAR | N14: =IF(D14="","-",IF(D14=0,"BELUM BAYAR",IF(D14<$F$2,"CICILAN",IF(D14>$F$2,"LUNAS (LEBIH)","LUNAS")))) -> BELUM BAYAR | O14: =IF(E14="","-",IF(E14=0,"BELUM BAYAR",IF(E14<$F$2,"CICILAN",IF(E14>$F$2,"LUNAS (LEBIH)","LUNAS")))) -> BELUM BAYAR | P14: =IF(F14="","-",IF(F14=0,"BELUM BAYAR",IF(F14<$F$2,"CICILAN",IF(F14>$F$2,"LUNAS (LEBIH)","LUNAS")))) -> BELUM BAYAR | Q14: =IF(G14="","-",IF(G14=0,"BELUM BAYAR",IF(G14<$F$2,"CICILAN",IF(G14>$F$2,"LUNAS (LEBIH)","LUNAS")))) -> -
A15: =MASTER_ANGGOTA!A15 -> 11 | B15: =MASTER_ANGGOTA!B15 -> Nama Siswa 11 | C15: =IF(1<=$D$2,SUMIFS(PEMBAYARAN!$E$4:$E$500,PEMBAYARAN!$A$4:$A$500,$B15,PEMBAYARAN!$B$4:$B$500,"September",PEMBAYARAN!$C$4:$C$500,"Minggu 1"),"") -> 0 | D15: =IF(2<=$D$2,SUMIFS(PEMBAYARAN!$E$4:$E$500,PEMBAYARAN!$A$4:$A$500,$B15,PEMBAYARAN!$B$4:$B$500,"September",PEMBAYARAN!$C$4:$C$500,"Minggu 2"),"") -> 0 | E15: =IF(3<=$D$2,SUMIFS(PEMBAYARAN!$E$4:$E$500,PEMBAYARAN!$A$4:$A$500,$B15,PEMBAYARAN!$B$4:$B$500,"September",PEMBAYARAN!$C$4:$C$500,"Minggu 3"),"") -> 0 | F15: =IF(4<=$D$2,SUMIFS(PEMBAYARAN!$E$4:$E$500,PEMBAYARAN!$A$4:$A$500,$B15,PEMBAYARAN!$B$4:$B$500,"September",PEMBAYARAN!$C$4:$C$500,"Minggu 4"),"") -> 0 | G15: =IF(5<=$D$2,SUMIFS(PEMBAYARAN!$E$4:$E$500,PEMBAYARAN!$A$4:$A$500,$B15,PEMBAYARAN!$B$4:$B$500,"September",PEMBAYARAN!$C$4:$C$500,"Minggu 5"),"") | H15: =MIN($D$2,5)*$F$2 -> 20000 | I15: =SUM(C15:G15) -> 0 | J15: =MAX(H15-I15,0) -> 20000 | K15: =MAX(I15-H15,0) -> 0 | L15: =IF(I15=0,"BELUM BAYAR",IF(I15<H15,"CICILAN",IF(I15>H15,"LUNAS (LEBIH)","LUNAS"))) -> BELUM BAYAR | M15: =IF(C15="","-",IF(C15=0,"BELUM BAYAR",IF(C15<$F$2,"CICILAN",IF(C15>$F$2,"LUNAS (LEBIH)","LUNAS")))) -> BELUM BAYAR | N15: =IF(D15="","-",IF(D15=0,"BELUM BAYAR",IF(D15<$F$2,"CICILAN",IF(D15>$F$2,"LUNAS (LEBIH)","LUNAS")))) -> BELUM BAYAR | O15: =IF(E15="","-",IF(E15=0,"BELUM BAYAR",IF(E15<$F$2,"CICILAN",IF(E15>$F$2,"LUNAS (LEBIH)","LUNAS")))) -> BELUM BAYAR | P15: =IF(F15="","-",IF(F15=0,"BELUM BAYAR",IF(F15<$F$2,"CICILAN",IF(F15>$F$2,"LUNAS (LEBIH)","LUNAS")))) -> BELUM BAYAR | Q15: =IF(G15="","-",IF(G15=0,"BELUM BAYAR",IF(G15<$F$2,"CICILAN",IF(G15>$F$2,"LUNAS (LEBIH)","LUNAS")))) -> -
A16: =MASTER_ANGGOTA!A16 -> 12 | B16: =MASTER_ANGGOTA!B16 -> Nama Siswa 12 | C16: =IF(1<=$D$2,SUMIFS(PEMBAYARAN!$E$4:$E$500,PEMBAYARAN!$A$4:$A$500,$B16,PEMBAYARAN!$B$4:$B$500,"September",PEMBAYARAN!$C$4:$C$500,"Minggu 1"),"") -> 0 | D16: =IF(2<=$D$2,SUMIFS(PEMBAYARAN!$E$4:$E$500,PEMBAYARAN!$A$4:$A$500,$B16,PEMBAYARAN!$B$4:$B$500,"September",PEMBAYARAN!$C$4:$C$500,"Minggu 2"),"") -> 0 | E16: =IF(3<=$D$2,SUMIFS(PEMBAYARAN!$E$4:$E$500,PEMBAYARAN!$A$4:$A$500,$B16,PEMBAYARAN!$B$4:$B$500,"September",PEMBAYARAN!$C$4:$C$500,"Minggu 3"),"") -> 0 | F16: =IF(4<=$D$2,SUMIFS(PEMBAYARAN!$E$4:$E$500,PEMBAYARAN!$A$4:$A$500,$B16,PEMBAYARAN!$B$4:$B$500,"September",PEMBAYARAN!$C$4:$C$500,"Minggu 4"),"") -> 0 | G16: =IF(5<=$D$2,SUMIFS(PEMBAYARAN!$E$4:$E$500,PEMBAYARAN!$A$4:$A$500,$B16,PEMBAYARAN!$B$4:$B$500,"September",PEMBAYARAN!$C$4:$C$500,"Minggu 5"),"") | H16: =MIN($D$2,5)*$F$2 -> 20000 | I16: =SUM(C16:G16) -> 0 | J16: =MAX(H16-I16,0) -> 20000 | K16: =MAX(I16-H16,0) -> 0 | L16: =IF(I16=0,"BELUM BAYAR",IF(I16<H16,"CICILAN",IF(I16>H16,"LUNAS (LEBIH)","LUNAS"))) -> BELUM BAYAR | M16: =IF(C16="","-",IF(C16=0,"BELUM BAYAR",IF(C16<$F$2,"CICILAN",IF(C16>$F$2,"LUNAS (LEBIH)","LUNAS")))) -> BELUM BAYAR | N16: =IF(D16="","-",IF(D16=0,"BELUM BAYAR",IF(D16<$F$2,"CICILAN",IF(D16>$F$2,"LUNAS (LEBIH)","LUNAS")))) -> BELUM BAYAR | O16: =IF(E16="","-",IF(E16=0,"BELUM BAYAR",IF(E16<$F$2,"CICILAN",IF(E16>$F$2,"LUNAS (LEBIH)","LUNAS")))) -> BELUM BAYAR | P16: =IF(F16="","-",IF(F16=0,"BELUM BAYAR",IF(F16<$F$2,"CICILAN",IF(F16>$F$2,"LUNAS (LEBIH)","LUNAS")))) -> BELUM BAYAR | Q16: =IF(G16="","-",IF(G16=0,"BELUM BAYAR",IF(G16<$F$2,"CICILAN",IF(G16>$F$2,"LUNAS (LEBIH)","LUNAS")))) -> -
... A45: =MASTER_ANGGOTA!A45 -> 41 | B45: =MASTER_ANGGOTA!B45 -> Nama Siswa 41 | C45: =IF(1<=$D$2,SUMIFS(PEMBAYARAN!$E$4:$E$500,PEMBAYARAN!$A$4:$A$500,$B45,PEMBAYARAN!$B$4:$B$500,"September",PEMBAYARAN!$C$4:$C$500,"Minggu 1"),"") -> 0 | D45: =IF(2<=$D$2,SUMIFS(PEMBAYARAN!$E$4:$E$500,PEMBAYARAN!$A$4:$A$500,$B45,PEMBAYARAN!$B$4:$B$500,"September",PEMBAYARAN!$C$4:$C$500,"Minggu 2"),"") -> 0 | E45: =IF(3<=$D$2,SUMIFS(PEMBAYARAN!$E$4:$E$500,PEMBAYARAN!$A$4:$A$500,$B45,PEMBAYARAN!$B$4:$B$500,"September",PEMBAYARAN!$C$4:$C$500,"Minggu 3"),"") -> 0 | F45: =IF(4<=$D$2,SUMIFS(PEMBAYARAN!$E$4:$E$500,PEMBAYARAN!$A$4:$A$500,$B45,PEMBAYARAN!$B$4:$B$500,"September",PEMBAYARAN!$C$4:$C$500,"Minggu 4"),"") -> 0 | G45: =IF(5<=$D$2,SUMIFS(PEMBAYARAN!$E$4:$E$500,PEMBAYARAN!$A$4:$A$500,$B45,PEMBAYARAN!$B$4:$B$500,"September",PEMBAYARAN!$C$4:$C$500,"Minggu 5"),"") | H45: =MIN($D$2,5)*$F$2 -> 20000 | I45: =SUM(C45:G45) -> 0 | J45: =MAX(H45-I45,0) -> 20000 | K45: =MAX(I45-H45,0) -> 0 | L45: =IF(I45=0,"BELUM BAYAR",IF(I45<H45,"CICILAN",IF(I45>H45,"LUNAS (LEBIH)","LUNAS"))) -> BELUM BAYAR | M45: =IF(C45="","-",IF(C45=0,"BELUM BAYAR",IF(C45<$F$2,"CICILAN",IF(C45>$F$2,"LUNAS (LEBIH)","LUNAS")))) -> BELUM BAYAR | N45: =IF(D45="","-",IF(D45=0,"BELUM BAYAR",IF(D45<$F$2,"CICILAN",IF(D45>$F$2,"LUNAS (LEBIH)","LUNAS")))) -> BELUM BAYAR | O45: =IF(E45="","-",IF(E45=0,"BELUM BAYAR",IF(E45<$F$2,"CICILAN",IF(E45>$F$2,"LUNAS (LEBIH)","LUNAS")))) -> BELUM BAYAR | P45: =IF(F45="","-",IF(F45=0,"BELUM BAYAR",IF(F45<$F$2,"CICILAN",IF(F45>$F$2,"LUNAS (LEBIH)","LUNAS")))) -> BELUM BAYAR | Q45: =IF(G45="","-",IF(G45=0,"BELUM BAYAR",IF(G45<$F$2,"CICILAN",IF(G45>$F$2,"LUNAS (LEBIH)","LUNAS")))) -> -
B47: TOTAL | H47: =SUM(H5:H45) -> 820000 | I47: =SUM(I5:I45) -> 25000 | J47: =SUM(J5:J45) -> 795000 | K47: =SUM(K5:K45) -> 0
B48: Jumlah Anggota LUNAS: | D48: =COUNTIF(L5:L45,"LUNAS")+COUNTIF(L5:L45,"LUNAS (LEBIH)") -> 0
B49: Jumlah Anggota CICILAN: | D49: =COUNTIF(L5:L45,"CICILAN") -> 3
B50: Jumlah Anggota BELUM BAYAR: | D50: =COUNTIF(L5:L45,"BELUM BAYAR") -> 38

Sheet KAS_OKTOBER
A1: REKAP KAS BULAN OKTOBER 2026/2027
A2: Jumlah Minggu Aktif Bulan Ini: | D2: 5 | E2: Iuran / Minggu: | F2: 5000
A3: Kuning = sel input (boleh diedit) | Putih = hasil formula (otomatis)
A4: No | B4: Nama | C4: Minggu 1 | D4: Minggu 2 | E4: Minggu 3 | F4: Minggu 4 | G4: Minggu 5 | H4: Total Wajib | I4: Total Dibayar | J4: Kekurangan | K4: Kelebihan | L4: Status | M4: Status M1 | N4: Status M2 | O4: Status M3 | P4: Status M4 | Q4: Status M5
A5: =MASTER_ANGGOTA!A5 -> 1 | B5: =MASTER_ANGGOTA!B5 -> Budi | C5: =IF(1<=$D$2,SUMIFS(PEMBAYARAN!$E$4:$E$500,PEMBAYARAN!$A$4:$A$500,$B5,PEMBAYARAN!$B$4:$B$500,"Oktober",PEMBAYARAN!$C$4:$C$500,"Minggu 1"),"") -> 0 | D5: =IF(2<=$D$2,SUMIFS(PEMBAYARAN!$E$4:$E$500,PEMBAYARAN!$A$4:$A$500,$B5,PEMBAYARAN!$B$4:$B$500,"Oktober",PEMBAYARAN!$C$4:$C$500,"Minggu 2"),"") -> 0 | E5: =IF(3<=$D$2,SUMIFS(PEMBAYARAN!$E$4:$E$500,PEMBAYARAN!$A$4:$A$500,$B5,PEMBAYARAN!$B$4:$B$500,"Oktober",PEMBAYARAN!$C$4:$C$500,"Minggu 3"),"") -> 0 | F5: =IF(4<=$D$2,SUMIFS(PEMBAYARAN!$E$4:$E$500,PEMBAYARAN!$A$4:$A$500,$B5,PEMBAYARAN!$B$4:$B$500,"Oktober",PEMBAYARAN!$C$4:$C$500,"Minggu 4"),"") -> 0 | G5: =IF(5<=$D$2,SUMIFS(PEMBAYARAN!$E$4:$E$500,PEMBAYARAN!$A$4:$A$500,$B5,PEMBAYARAN!$B$4:$B$500,"Oktober",PEMBAYARAN!$C$4:$C$500,"Minggu 5"),"") -> 0 | H5: =MIN($D$2,5)*$F$2 -> 25000 | I5: =SUM(C5:G5) -> 0 | J5: =MAX(H5-I5,0) -> 25000 | K5: =MAX(I5-H5,0) -> 0 | L5: =IF(I5=0,"BELUM BAYAR",IF(I5<H5,"CICILAN",IF(I5>H5,"LUNAS (LEBIH)","LUNAS"))) -> BELUM BAYAR | M5: =IF(C5="","-",IF(C5=0,"BELUM BAYAR",IF(C5<$F$2,"CICILAN",IF(C5>$F$2,"LUNAS (LEBIH)","LUNAS")))) -> BELUM BAYAR | N5: =IF(D5="","-",IF(D5=0,"BELUM BAYAR",IF(D5<$F$2,"CICILAN",IF(D5>$F$2,"LUNAS (LEBIH)","LUNAS")))) -> BELUM BAYAR | O5: =IF(E5="","-",IF(E5=0,"BELUM BAYAR",IF(E5<$F$2,"CICILAN",IF(E5>$F$2,"LUNAS (LEBIH)","LUNAS")))) -> BELUM BAYAR | P5: =IF(F5="","-",IF(F5=0,"BELUM BAYAR",IF(F5<$F$2,"CICILAN",IF(F5>$F$2,"LUNAS (LEBIH)","LUNAS")))) -> BELUM BAYAR | Q5: =IF(G5="","-",IF(G5=0,"BELUM BAYAR",IF(G5<$F$2,"CICILAN",IF(G5>$F$2,"LUNAS (LEBIH)","LUNAS")))) -> BELUM BAYAR
A6: =MASTER_ANGGOTA!A6 -> 2 | B6: =MASTER_ANGGOTA!B6 -> Andi | C6: =IF(1<=$D$2,SUMIFS(PEMBAYARAN!$E$4:$E$500,PEMBAYARAN!$A$4:$A$500,$B6,PEMBAYARAN!$B$4:$B$500,"Oktober",PEMBAYARAN!$C$4:$C$500,"Minggu 1"),"") -> 0 | D6: =IF(2<=$D$2,SUMIFS(PEMBAYARAN!$E$4:$E$500,PEMBAYARAN!$A$4:$A$500,$B6,PEMBAYARAN!$B$4:$B$500,"Oktober",PEMBAYARAN!$C$4:$C$500,"Minggu 2"),"") -> 0 | E6: =IF(3<=$D$2,SUMIFS(PEMBAYARAN!$E$4:$E$500,PEMBAYARAN!$A$4:$A$500,$B6,PEMBAYARAN!$B$4:$B$500,"Oktober",PEMBAYARAN!$C$4:$C$500,"Minggu 3"),"") -> 0 | F6: =IF(4<=$D$2,SUMIFS(PEMBAYARAN!$E$4:$E$500,PEMBAYARAN!$A$4:$A$500,$B6,PEMBAYARAN!$B$4:$B$500,"Oktober",PEMBAYARAN!$C$4:$C$500,"Minggu 4"),"") -> 0 | G6: =IF(5<=$D$2,SUMIFS(PEMBAYARAN!$E$4:$E$500,PEMBAYARAN!$A$4:$A$500,$B6,PEMBAYARAN!$B$4:$B$500,"Oktober",PEMBAYARAN!$C$4:$C$500,"Minggu 5"),"") -> 0 | H6: =MIN($D$2,5)*$F$2 -> 25000 | I6: =SUM(C6:G6) -> 0 | J6: =MAX(H6-I6,0) -> 25000 | K6: =MAX(I6-H6,0) -> 0 | L6: =IF(I6=0,"BELUM BAYAR",IF(I6<H6,"CICILAN",IF(I6>H6,"LUNAS (LEBIH)","LUNAS"))) -> BELUM BAYAR | M6: =IF(C6="","-",IF(C6=0,"BELUM BAYAR",IF(C6<$F$2,"CICILAN",IF(C6>$F$2,"LUNAS (LEBIH)","LUNAS")))) -> BELUM BAYAR | N6: =IF(D6="","-",IF(D6=0,"BELUM BAYAR",IF(D6<$F$2,"CICILAN",IF(D6>$F$2,"LUNAS (LEBIH)","LUNAS")))) -> BELUM BAYAR | O6: =IF(E6="","-",IF(E6=0,"BELUM BAYAR",IF(E6<$F$2,"CICILAN",IF(E6>$F$2,"LUNAS (LEBIH)","LUNAS")))) -> BELUM BAYAR | P6: =IF(F6="","-",IF(F6=0,"BELUM BAYAR",IF(F6<$F$2,"CICILAN",IF(F6>$F$2,"LUNAS (LEBIH)","LUNAS")))) -> BELUM BAYAR | Q6: =IF(G6="","-",IF(G6=0,"BELUM BAYAR",IF(G6<$F$2,"CICILAN",IF(G6>$F$2,"LUNAS (LEBIH)","LUNAS")))) -> BELUM BAYAR
A7: =MASTER_ANGGOTA!A7 -> 3 | B7: =MASTER_ANGGOTA!B7 -> Citra | C7: =IF(1<=$D$2,SUMIFS(PEMBAYARAN!$E$4:$E$500,PEMBAYARAN!$A$4:$A$500,$B7,PEMBAYARAN!$B$4:$B$500,"Oktober",PEMBAYARAN!$C$4:$C$500,"Minggu 1"),"") -> 0 | D7: =IF(2<=$D$2,SUMIFS(PEMBAYARAN!$E$4:$E$500,PEMBAYARAN!$A$4:$A$500,$B7,PEMBAYARAN!$B$4:$B$500,"Oktober",PEMBAYARAN!$C$4:$C$500,"Minggu 2"),"") -> 0 | E7: =IF(3<=$D$2,SUMIFS(PEMBAYARAN!$E$4:$E$500,PEMBAYARAN!$A$4:$A$500,$B7,PEMBAYARAN!$B$4:$B$500,"Oktober",PEMBAYARAN!$C$4:$C$500,"Minggu 3"),"") -> 0 | F7: =IF(4<=$D$2,SUMIFS(PEMBAYARAN!$E$4:$E$500,PEMBAYARAN!$A$4:$A$500,$B7,PEMBAYARAN!$B$4:$B$500,"Oktober",PEMBAYARAN!$C$4:$C$500,"Minggu 4"),"") -> 0 | G7: =IF(5<=$D$2,SUMIFS(PEMBAYARAN!$E$4:$E$500,PEMBAYARAN!$A$4:$A$500,$B7,PEMBAYARAN!$B$4:$B$500,"Oktober",PEMBAYARAN!$C$4:$C$500,"Minggu 5"),"") -> 0 | H7: =MIN($D$2,5)*$F$2 -> 25000 | I7: =SUM(C7:G7) -> 0 | J7: =MAX(H7-I7,0) -> 25000 | K7: =MAX(I7-H7,0) -> 0 | L7: =IF(I7=0,"BELUM BAYAR",IF(I7<H7,"CICILAN",IF(I7>H7,"LUNAS (LEBIH)","LUNAS"))) -> BELUM BAYAR | M7: =IF(C7="","-",IF(C7=0,"BELUM BAYAR",IF(C7<$F$2,"CICILAN",IF(C7>$F$2,"LUNAS (LEBIH)","LUNAS")))) -> BELUM BAYAR | N7: =IF(D7="","-",IF(D7=0,"BELUM BAYAR",IF(D7<$F$2,"CICILAN",IF(D7>$F$2,"LUNAS (LEBIH)","LUNAS")))) -> BELUM BAYAR | O7: =IF(E7="","-",IF(E7=0,"BELUM BAYAR",IF(E7<$F$2,"CICILAN",IF(E7>$F$2,"LUNAS (LEBIH)","LUNAS")))) -> BELUM BAYAR | P7: =IF(F7="","-",IF(F7=0,"BELUM BAYAR",IF(F7<$F$2,"CICILAN",IF(F7>$F$2,"LUNAS (LEBIH)","LUNAS")))) -> BELUM BAYAR | Q7: =IF(G7="","-",IF(G7=0,"BELUM BAYAR",IF(G7<$F$2,"CICILAN",IF(G7>$F$2,"LUNAS (LEBIH)","LUNAS")))) -> BELUM BAYAR
A8: =MASTER_ANGGOTA!A8 -> 4 | B8: =MASTER_ANGGOTA!B8 -> Doni | C8: =IF(1<=$D$2,SUMIFS(PEMBAYARAN!$E$4:$E$500,PEMBAYARAN!$A$4:$A$500,$B8,PEMBAYARAN!$B$4:$B$500,"Oktober",PEMBAYARAN!$C$4:$C$500,"Minggu 1"),"") -> 0 | D8: =IF(2<=$D$2,SUMIFS(PEMBAYARAN!$E$4:$E$500,PEMBAYARAN!$A$4:$A$500,$B8,PEMBAYARAN!$B$4:$B$500,"Oktober",PEMBAYARAN!$C$4:$C$500,"Minggu 2"),"") -> 0 | E8: =IF(3<=$D$2,SUMIFS(PEMBAYARAN!$E$4:$E$500,PEMBAYARAN!$A$4:$A$500,$B8,PEMBAYARAN!$B$4:$B$500,"Oktober",PEMBAYARAN!$C$4:$C$500,"Minggu 3"),"") -> 0 | F8: =IF(4<=$D$2,SUMIFS(PEMBAYARAN!$E$4:$E$500,PEMBAYARAN!$A$4:$A$500,$B8,PEMBAYARAN!$B$4:$B$500,"Oktober",PEMBAYARAN!$C$4:$C$500,"Minggu 4"),"") -> 0 | G8: =IF(5<=$D$2,SUMIFS(PEMBAYARAN!$E$4:$E$500,PEMBAYARAN!$A$4:$A$500,$B8,PEMBAYARAN!$B$4:$B$500,"Oktober",PEMBAYARAN!$C$4:$C$500,"Minggu 5"),"") -> 0 | H8: =MIN($D$2,5)*$F$2 -> 25000 | I8: =SUM(C8:G8) -> 0 | J8: =MAX(H8-I8,0) -> 25000 | K8: =MAX(I8-H8,0) -> 0 | L8: =IF(I8=0,"BELUM BAYAR",IF(I8<H8,"CICILAN",IF(I8>H8,"LUNAS (LEBIH)","LUNAS"))) -> BELUM BAYAR | M8: =IF(C8="","-",IF(C8=0,"BELUM BAYAR",IF(C8<$F$2,"CICILAN",IF(C8>$F$2,"LUNAS (LEBIH)","LUNAS")))) -> BELUM BAYAR | N8: =IF(D8="","-",IF(D8=0,"BELUM BAYAR",IF(D8<$F$2,"CICILAN",IF(D8>$F$2,"LUNAS (LEBIH)","LUNAS")))) -> BELUM BAYAR | O8: =IF(E8="","-",IF(E8=0,"BELUM BAYAR",IF(E8<$F$2,"CICILAN",IF(E8>$F$2,"LUNAS (LEBIH)","LUNAS")))) -> BELUM BAYAR | P8: =IF(F8="","-",IF(F8=0,"BELUM BAYAR",IF(F8<$F$2,"CICILAN",IF(F8>$F$2,"LUNAS (LEBIH)","LUNAS")))) -> BELUM BAYAR | Q8: =IF(G8="","-",IF(G8=0,"BELUM BAYAR",IF(G8<$F$2,"CICILAN",IF(G8>$F$2,"LUNAS (LEBIH)","LUNAS")))) -> BELUM BAYAR
A9: =MASTER_ANGGOTA!A9 -> 5 | B9: =MASTER_ANGGOTA!B9 -> Nama Siswa 5 | C9: =IF(1<=$D$2,SUMIFS(PEMBAYARAN!$E$4:$E$500,PEMBAYARAN!$A$4:$A$500,$B9,PEMBAYARAN!$B$4:$B$500,"Oktober",PEMBAYARAN!$C$4:$C$500,"Minggu 1"),"") -> 0 | D9: =IF(2<=$D$2,SUMIFS(PEMBAYARAN!$E$4:$E$500,PEMBAYARAN!$A$4:$A$500,$B9,PEMBAYARAN!$B$4:$B$500,"Oktober",PEMBAYARAN!$C$4:$C$500,"Minggu 2"),"") -> 0 | E9: =IF(3<=$D$2,SUMIFS(PEMBAYARAN!$E$4:$E$500,PEMBAYARAN!$A$4:$A$500,$B9,PEMBAYARAN!$B$4:$B$500,"Oktober",PEMBAYARAN!$C$4:$C$500,"Minggu 3"),"") -> 0 | F9: =IF(4<=$D$2,SUMIFS(PEMBAYARAN!$E$4:$E$500,PEMBAYARAN!$A$4:$A$500,$B9,PEMBAYARAN!$B$4:$B$500,"Oktober",PEMBAYARAN!$C$4:$C$500,"Minggu 4"),"") -> 0 | G9: =IF(5<=$D$2,SUMIFS(PEMBAYARAN!$E$4:$E$500,PEMBAYARAN!$A$4:$A$500,$B9,PEMBAYARAN!$B$4:$B$500,"Oktober",PEMBAYARAN!$C$4:$C$500,"Minggu 5"),"") -> 0 | H9: =MIN($D$2,5)*$F$2 -> 25000 | I9: =SUM(C9:G9) -> 0 | J9: =MAX(H9-I9,0) -> 25000 | K9: =MAX(I9-H9,0) -> 0 | L9: =IF(I9=0,"BELUM BAYAR",IF(I9<H9,"CICILAN",IF(I9>H9,"LUNAS (LEBIH)","LUNAS"))) -> BELUM BAYAR | M9: =IF(C9="","-",IF(C9=0,"BELUM BAYAR",IF(C9<$F$2,"CICILAN",IF(C9>$F$2,"LUNAS (LEBIH)","LUNAS")))) -> BELUM BAYAR | N9: =IF(D9="","-",IF(D9=0,"BELUM BAYAR",IF(D9<$F$2,"CICILAN",IF(D9>$F$2,"LUNAS (LEBIH)","LUNAS")))) -> BELUM BAYAR | O9: =IF(E9="","-",IF(E9=0,"BELUM BAYAR",IF(E9<$F$2,"CICILAN",IF(E9>$F$2,"LUNAS (LEBIH)","LUNAS")))) -> BELUM BAYAR | P9: =IF(F9="","-",IF(F9=0,"BELUM BAYAR",IF(F9<$F$2,"CICILAN",IF(F9>$F$2,"LUNAS (LEBIH)","LUNAS")))) -> BELUM BAYAR | Q9: =IF(G9="","-",IF(G9=0,"BELUM BAYAR",IF(G9<$F$2,"CICILAN",IF(G9>$F$2,"LUNAS (LEBIH)","LUNAS")))) -> BELUM BAYAR
A10: =MASTER_ANGGOTA!A10 -> 6 | B10: =MASTER_ANGGOTA!B10 -> Nama Siswa 6 | C10: =IF(1<=$D$2,SUMIFS(PEMBAYARAN!$E$4:$E$500,PEMBAYARAN!$A$4:$A$500,$B10,PEMBAYARAN!$B$4:$B$500,"Oktober",PEMBAYARAN!$C$4:$C$500,"Minggu 1"),"") -> 0 | D10: =IF(2<=$D$2,SUMIFS(PEMBAYARAN!$E$4:$E$500,PEMBAYARAN!$A$4:$A$500,$B10,PEMBAYARAN!$B$4:$B$500,"Oktober",PEMBAYARAN!$C$4:$C$500,"Minggu 2"),"") -> 0 | E10: =IF(3<=$D$2,SUMIFS(PEMBAYARAN!$E$4:$E$500,PEMBAYARAN!$A$4:$A$500,$B10,PEMBAYARAN!$B$4:$B$500,"Oktober",PEMBAYARAN!$C$4:$C$500,"Minggu 3"),"") -> 0 | F10: =IF(4<=$D$2,SUMIFS(PEMBAYARAN!$E$4:$E$500,PEMBAYARAN!$A$4:$A$500,$B10,PEMBAYARAN!$B$4:$B$500,"Oktober",PEMBAYARAN!$C$4:$C$500,"Minggu 4"),"") -> 0 | G10: =IF(5<=$D$2,SUMIFS(PEMBAYARAN!$E$4:$E$500,PEMBAYARAN!$A$4:$A$500,$B10,PEMBAYARAN!$B$4:$B$500,"Oktober",PEMBAYARAN!$C$4:$C$500,"Minggu 5"),"") -> 0 | H10: =MIN($D$2,5)*$F$2 -> 25000 | I10: =SUM(C10:G10) -> 0 | J10: =MAX(H10-I10,0) -> 25000 | K10: =MAX(I10-H10,0) -> 0 | L10: =IF(I10=0,"BELUM BAYAR",IF(I10<H10,"CICILAN",IF(I10>H10,"LUNAS (LEBIH)","LUNAS"))) -> BELUM BAYAR | M10: =IF(C10="","-",IF(C10=0,"BELUM BAYAR",IF(C10<$F$2,"CICILAN",IF(C10>$F$2,"LUNAS (LEBIH)","LUNAS")))) -> BELUM BAYAR | N10: =IF(D10="","-",IF(D10=0,"BELUM BAYAR",IF(D10<$F$2,"CICILAN",IF(D10>$F$2,"LUNAS (LEBIH)","LUNAS")))) -> BELUM BAYAR | O10: =IF(E10="","-",IF(E10=0,"BELUM BAYAR",IF(E10<$F$2,"CICILAN",IF(E10>$F$2,"LUNAS (LEBIH)","LUNAS")))) -> BELUM BAYAR | P10: =IF(F10="","-",IF(F10=0,"BELUM BAYAR",IF(F10<$F$2,"CICILAN",IF(F10>$F$2,"LUNAS (LEBIH)","LUNAS")))) -> BELUM BAYAR | Q10: =IF(G10="","-",IF(G10=0,"BELUM BAYAR",IF(G10<$F$2,"CICILAN",IF(G10>$F$2,"LUNAS (LEBIH)","LUNAS")))) -> BELUM BAYAR
A11: =MASTER_ANGGOTA!A11 -> 7 | B11: =MASTER_ANGGOTA!B11 -> Nama Siswa 7 | C11: =IF(1<=$D$2,SUMIFS(PEMBAYARAN!$E$4:$E$500,PEMBAYARAN!$A$4:$A$500,$B11,PEMBAYARAN!$B$4:$B$500,"Oktober",PEMBAYARAN!$C$4:$C$500,"Minggu 1"),"") -> 0 | D11: =IF(2<=$D$2,SUMIFS(PEMBAYARAN!$E$4:$E$500,PEMBAYARAN!$A$4:$A$500,$B11,PEMBAYARAN!$B$4:$B$500,"Oktober",PEMBAYARAN!$C$4:$C$500,"Minggu 2"),"") -> 0 | E11: =IF(3<=$D$2,SUMIFS(PEMBAYARAN!$E$4:$E$500,PEMBAYARAN!$A$4:$A$500,$B11,PEMBAYARAN!$B$4:$B$500,"Oktober",PEMBAYARAN!$C$4:$C$500,"Minggu 3"),"") -> 0 | F11: =IF(4<=$D$2,SUMIFS(PEMBAYARAN!$E$4:$E$500,PEMBAYARAN!$A$4:$A$500,$B11,PEMBAYARAN!$B$4:$B$500,"Oktober",PEMBAYARAN!$C$4:$C$500,"Minggu 4"),"") -> 0 | G11: =IF(5<=$D$2,SUMIFS(PEMBAYARAN!$E$4:$E$500,PEMBAYARAN!$A$4:$A$500,$B11,PEMBAYARAN!$B$4:$B$500,"Oktober",PEMBAYARAN!$C$4:$C$500,"Minggu 5"),"") -> 0 | H11: =MIN($D$2,5)*$F$2 -> 25000 | I11: =SUM(C11:G11) -> 0 | J11: =MAX(H11-I11,0) -> 25000 | K11: =MAX(I11-H11,0) -> 0 | L11: =IF(I11=0,"BELUM BAYAR",IF(I11<H11,"CICILAN",IF(I11>H11,"LUNAS (LEBIH)","LUNAS"))) -> BELUM BAYAR | M11: =IF(C11="","-",IF(C11=0,"BELUM BAYAR",IF(C11<$F$2,"CICILAN",IF(C11>$F$2,"LUNAS (LEBIH)","LUNAS")))) -> BELUM BAYAR | N11: =IF(D11="","-",IF(D11=0,"BELUM BAYAR",IF(D11<$F$2,"CICILAN",IF(D11>$F$2,"LUNAS (LEBIH)","LUNAS")))) -> BELUM BAYAR | O11: =IF(E11="","-",IF(E11=0,"BELUM BAYAR",IF(E11<$F$2,"CICILAN",IF(E11>$F$2,"LUNAS (LEBIH)","LUNAS")))) -> BELUM BAYAR | P11: =IF(F11="","-",IF(F11=0,"BELUM BAYAR",IF(F11<$F$2,"CICILAN",IF(F11>$F$2,"LUNAS (LEBIH)","LUNAS")))) -> BELUM BAYAR | Q11: =IF(G11="","-",IF(G11=0,"BELUM BAYAR",IF(G11<$F$2,"CICILAN",IF(G11>$F$2,"LUNAS (LEBIH)","LUNAS")))) -> BELUM BAYAR
A12: =MASTER_ANGGOTA!A12 -> 8 | B12: =MASTER_ANGGOTA!B12 -> Nama Siswa 8 | C12: =IF(1<=$D$2,SUMIFS(PEMBAYARAN!$E$4:$E$500,PEMBAYARAN!$A$4:$A$500,$B12,PEMBAYARAN!$B$4:$B$500,"Oktober",PEMBAYARAN!$C$4:$C$500,"Minggu 1"),"") -> 0 | D12: =IF(2<=$D$2,SUMIFS(PEMBAYARAN!$E$4:$E$500,PEMBAYARAN!$A$4:$A$500,$B12,PEMBAYARAN!$B$4:$B$500,"Oktober",PEMBAYARAN!$C$4:$C$500,"Minggu 2"),"") -> 0 | E12: =IF(3<=$D$2,SUMIFS(PEMBAYARAN!$E$4:$E$500,PEMBAYARAN!$A$4:$A$500,$B12,PEMBAYARAN!$B$4:$B$500,"Oktober",PEMBAYARAN!$C$4:$C$500,"Minggu 3"),"") -> 0 | F12: =IF(4<=$D$2,SUMIFS(PEMBAYARAN!$E$4:$E$500,PEMBAYARAN!$A$4:$A$500,$B12,PEMBAYARAN!$B$4:$B$500,"Oktober",PEMBAYARAN!$C$4:$C$500,"Minggu 4"),"") -> 0 | G12: =IF(5<=$D$2,SUMIFS(PEMBAYARAN!$E$4:$E$500,PEMBAYARAN!$A$4:$A$500,$B12,PEMBAYARAN!$B$4:$B$500,"Oktober",PEMBAYARAN!$C$4:$C$500,"Minggu 5"),"") -> 0 | H12: =MIN($D$2,5)*$F$2 -> 25000 | I12: =SUM(C12:G12) -> 0 | J12: =MAX(H12-I12,0) -> 25000 | K12: =MAX(I12-H12,0) -> 0 | L12: =IF(I12=0,"BELUM BAYAR",IF(I12<H12,"CICILAN",IF(I12>H12,"LUNAS (LEBIH)","LUNAS"))) -> BELUM BAYAR | M12: =IF(C12="","-",IF(C12=0,"BELUM BAYAR",IF(C12<$F$2,"CICILAN",IF(C12>$F$2,"LUNAS (LEBIH)","LUNAS")))) -> BELUM BAYAR | N12: =IF(D12="","-",IF(D12=0,"BELUM BAYAR",IF(D12<$F$2,"CICILAN",IF(D12>$F$2,"LUNAS (LEBIH)","LUNAS")))) -> BELUM BAYAR | O12: =IF(E12="","-",IF(E12=0,"BELUM BAYAR",IF(E12<$F$2,"CICILAN",IF(E12>$F$2,"LUNAS (LEBIH)","LUNAS")))) -> BELUM BAYAR | P12: =IF(F12="","-",IF(F12=0,"BELUM BAYAR",IF(F12<$F$2,"CICILAN",IF(F12>$F$2,"LUNAS (LEBIH)","LUNAS")))) -> BELUM BAYAR | Q12: =IF(G12="","-",IF(G12=0,"BELUM BAYAR",IF(G12<$F$2,"CICILAN",IF(G12>$F$2,"LUNAS (LEBIH)","LUNAS")))) -> BELUM BAYAR
A13: =MASTER_ANGGOTA!A13 -> 9 | B13: =MASTER_ANGGOTA!B13 -> Nama Siswa 9 | C13: =IF(1<=$D$2,SUMIFS(PEMBAYARAN!$E$4:$E$500,PEMBAYARAN!$A$4:$A$500,$B13,PEMBAYARAN!$B$4:$B$500,"Oktober",PEMBAYARAN!$C$4:$C$500,"Minggu 1"),"") -> 0 | D13: =IF(2<=$D$2,SUMIFS(PEMBAYARAN!$E$4:$E$500,PEMBAYARAN!$A$4:$A$500,$B13,PEMBAYARAN!$B$4:$B$500,"Oktober",PEMBAYARAN!$C$4:$C$500,"Minggu 2"),"") -> 0 | E13: =IF(3<=$D$2,SUMIFS(PEMBAYARAN!$E$4:$E$500,PEMBAYARAN!$A$4:$A$500,$B13,PEMBAYARAN!$B$4:$B$500,"Oktober",PEMBAYARAN!$C$4:$C$500,"Minggu 3"),"") -> 0 | F13: =IF(4<=$D$2,SUMIFS(PEMBAYARAN!$E$4:$E$500,PEMBAYARAN!$A$4:$A$500,$B13,PEMBAYARAN!$B$4:$B$500,"Oktober",PEMBAYARAN!$C$4:$C$500,"Minggu 4"),"") -> 0 | G13: =IF(5<=$D$2,SUMIFS(PEMBAYARAN!$E$4:$E$500,PEMBAYARAN!$A$4:$A$500,$B13,PEMBAYARAN!$B$4:$B$500,"Oktober",PEMBAYARAN!$C$4:$C$500,"Minggu 5"),"") -> 0 | H13: =MIN($D$2,5)*$F$2 -> 25000 | I13: =SUM(C13:G13) -> 0 | J13: =MAX(H13-I13,0) -> 25000 | K13: =MAX(I13-H13,0) -> 0 | L13: =IF(I13=0,"BELUM BAYAR",IF(I13<H13,"CICILAN",IF(I13>H13,"LUNAS (LEBIH)","LUNAS"))) -> BELUM BAYAR | M13: =IF(C13="","-",IF(C13=0,"BELUM BAYAR",IF(C13<$F$2,"CICILAN",IF(C13>$F$2,"LUNAS (LEBIH)","LUNAS")))) -> BELUM BAYAR | N13: =IF(D13="","-",IF(D13=0,"BELUM BAYAR",IF(D13<$F$2,"CICILAN",IF(D13>$F$2,"LUNAS (LEBIH)","LUNAS")))) -> BELUM BAYAR | O13: =IF(E13="","-",IF(E13=0,"BELUM BAYAR",IF(E13<$F$2,"CICILAN",IF(E13>$F$2,"LUNAS (LEBIH)","LUNAS")))) -> BELUM BAYAR | P13: =IF(F13="","-",IF(F13=0,"BELUM BAYAR",IF(F13<$F$2,"CICILAN",IF(F13>$F$2,"LUNAS (LEBIH)","LUNAS")))) -> BELUM BAYAR | Q13: =IF(G13="","-",IF(G13=0,"BELUM BAYAR",IF(G13<$F$2,"CICILAN",IF(G13>$F$2,"LUNAS (LEBIH)","LUNAS")))) -> BELUM BAYAR
A14: =MASTER_ANGGOTA!A14 -> 10 | B14: =MASTER_ANGGOTA!B14 -> Nama Siswa 10 | C14: =IF(1<=$D$2,SUMIFS(PEMBAYARAN!$E$4:$E$500,PEMBAYARAN!$A$4:$A$500,$B14,PEMBAYARAN!$B$4:$B$500,"Oktober",PEMBAYARAN!$C$4:$C$500,"Minggu 1"),"") -> 0 | D14: =IF(2<=$D$2,SUMIFS(PEMBAYARAN!$E$4:$E$500,PEMBAYARAN!$A$4:$A$500,$B14,PEMBAYARAN!$B$4:$B$500,"Oktober",PEMBAYARAN!$C$4:$C$500,"Minggu 2"),"") -> 0 | E14: =IF(3<=$D$2,SUMIFS(PEMBAYARAN!$E$4:$E$500,PEMBAYARAN!$A$4:$A$500,$B14,PEMBAYARAN!$B$4:$B$500,"Oktober",PEMBAYARAN!$C$4:$C$500,"Minggu 3"),"") -> 0 | F14: =IF(4<=$D$2,SUMIFS(PEMBAYARAN!$E$4:$E$500,PEMBAYARAN!$A$4:$A$500,$B14,PEMBAYARAN!$B$4:$B$500,"Oktober",PEMBAYARAN!$C$4:$C$500,"Minggu 4"),"") -> 0 | G14: =IF(5<=$D$2,SUMIFS(PEMBAYARAN!$E$4:$E$500,PEMBAYARAN!$A$4:$A$500,$B14,PEMBAYARAN!$B$4:$B$500,"Oktober",PEMBAYARAN!$C$4:$C$500,"Minggu 5"),"") -> 0 | H14: =MIN($D$2,5)*$F$2 -> 25000 | I14: =SUM(C14:G14) -> 0 | J14: =MAX(H14-I14,0) -> 25000 | K14: =MAX(I14-H14,0) -> 0 | L14: =IF(I14=0,"BELUM BAYAR",IF(I14<H14,"CICILAN",IF(I14>H14,"LUNAS (LEBIH)","LUNAS"))) -> BELUM BAYAR | M14: =IF(C14="","-",IF(C14=0,"BELUM BAYAR",IF(C14<$F$2,"CICILAN",IF(C14>$F$2,"LUNAS (LEBIH)","LUNAS")))) -> BELUM BAYAR | N14: =IF(D14="","-",IF(D14=0,"BELUM BAYAR",IF(D14<$F$2,"CICILAN",IF(D14>$F$2,"LUNAS (LEBIH)","LUNAS")))) -> BELUM BAYAR | O14: =IF(E14="","-",IF(E14=0,"BELUM BAYAR",IF(E14<$F$2,"CICILAN",IF(E14>$F$2,"LUNAS (LEBIH)","LUNAS")))) -> BELUM BAYAR | P14: =IF(F14="","-",IF(F14=0,"BELUM BAYAR",IF(F14<$F$2,"CICILAN",IF(F14>$F$2,"LUNAS (LEBIH)","LUNAS")))) -> BELUM BAYAR | Q14: =IF(G14="","-",IF(G14=0,"BELUM BAYAR",IF(G14<$F$2,"CICILAN",IF(G14>$F$2,"LUNAS (LEBIH)","LUNAS")))) -> BELUM BAYAR
A15: =MASTER_ANGGOTA!A15 -> 11 | B15: =MASTER_ANGGOTA!B15 -> Nama Siswa 11 | C15: =IF(1<=$D$2,SUMIFS(PEMBAYARAN!$E$4:$E$500,PEMBAYARAN!$A$4:$A$500,$B15,PEMBAYARAN!$B$4:$B$500,"Oktober",PEMBAYARAN!$C$4:$C$500,"Minggu 1"),"") -> 0 | D15: =IF(2<=$D$2,SUMIFS(PEMBAYARAN!$E$4:$E$500,PEMBAYARAN!$A$4:$A$500,$B15,PEMBAYARAN!$B$4:$B$500,"Oktober",PEMBAYARAN!$C$4:$C$500,"Minggu 2"),"") -> 0 | E15: =IF(3<=$D$2,SUMIFS(PEMBAYARAN!$E$4:$E$500,PEMBAYARAN!$A$4:$A$500,$B15,PEMBAYARAN!$B$4:$B$500,"Oktober",PEMBAYARAN!$C$4:$C$500,"Minggu 3"),"") -> 0 | F15: =IF(4<=$D$2,SUMIFS(PEMBAYARAN!$E$4:$E$500,PEMBAYARAN!$A$4:$A$500,$B15,PEMBAYARAN!$B$4:$B$500,"Oktober",PEMBAYARAN!$C$4:$C$500,"Minggu 4"),"") -> 0 | G15: =IF(5<=$D$2,SUMIFS(PEMBAYARAN!$E$4:$E$500,PEMBAYARAN!$A$4:$A$500,$B15,PEMBAYARAN!$B$4:$B$500,"Oktober",PEMBAYARAN!$C$4:$C$500,"Minggu 5"),"") -> 0 | H15: =MIN($D$2,5)*$F$2 -> 25000 | I15: =SUM(C15:G15) -> 0 | J15: =MAX(H15-I15,0) -> 25000 | K15: =MAX(I15-H15,0) -> 0 | L15: =IF(I15=0,"BELUM BAYAR",IF(I15<H15,"CICILAN",IF(I15>H15,"LUNAS (LEBIH)","LUNAS"))) -> BELUM BAYAR | M15: =IF(C15="","-",IF(C15=0,"BELUM BAYAR",IF(C15<$F$2,"CICILAN",IF(C15>$F$2,"LUNAS (LEBIH)","LUNAS")))) -> BELUM BAYAR | N15: =IF(D15="","-",IF(D15=0,"BELUM BAYAR",IF(D15<$F$2,"CICILAN",IF(D15>$F$2,"LUNAS (LEBIH)","LUNAS")))) -> BELUM BAYAR | O15: =IF(E15="","-",IF(E15=0,"BELUM BAYAR",IF(E15<$F$2,"CICILAN",IF(E15>$F$2,"LUNAS (LEBIH)","LUNAS")))) -> BELUM BAYAR | P15: =IF(F15="","-",IF(F15=0,"BELUM BAYAR",IF(F15<$F$2,"CICILAN",IF(F15>$F$2,"LUNAS (LEBIH)","LUNAS")))) -> BELUM BAYAR | Q15: =IF(G15="","-",IF(G15=0,"BELUM BAYAR",IF(G15<$F$2,"CICILAN",IF(G15>$F$2,"LUNAS (LEBIH)","LUNAS")))) -> BELUM BAYAR
A16: =MASTER_ANGGOTA!A16 -> 12 | B16: =MASTER_ANGGOTA!B16 -> Nama Siswa 12 | C16: =IF(1<=$D$2,SUMIFS(PEMBAYARAN!$E$4:$E$500,PEMBAYARAN!$A$4:$A$500,$B16,PEMBAYARAN!$B$4:$B$500,"Oktober",PEMBAYARAN!$C$4:$C$500,"Minggu 1"),"") -> 0 | D16: =IF(2<=$D$2,SUMIFS(PEMBAYARAN!$E$4:$E$500,PEMBAYARAN!$A$4:$A$500,$B16,PEMBAYARAN!$B$4:$B$500,"Oktober",PEMBAYARAN!$C$4:$C$500,"Minggu 2"),"") -> 0 | E16: =IF(3<=$D$2,SUMIFS(PEMBAYARAN!$E$4:$E$500,PEMBAYARAN!$A$4:$A$500,$B16,PEMBAYARAN!$B$4:$B$500,"Oktober",PEMBAYARAN!$C$4:$C$500,"Minggu 3"),"") -> 0 | F16: =IF(4<=$D$2,SUMIFS(PEMBAYARAN!$E$4:$E$500,PEMBAYARAN!$A$4:$A$500,$B16,PEMBAYARAN!$B$4:$B$500,"Oktober",PEMBAYARAN!$C$4:$C$500,"Minggu 4"),"") -> 0 | G16: =IF(5<=$D$2,SUMIFS(PEMBAYARAN!$E$4:$E$500,PEMBAYARAN!$A$4:$A$500,$B16,PEMBAYARAN!$B$4:$B$500,"Oktober",PEMBAYARAN!$C$4:$C$500,"Minggu 5"),"") -> 0 | H16: =MIN($D$2,5)*$F$2 -> 25000 | I16: =SUM(C16:G16) -> 0 | J16: =MAX(H16-I16,0) -> 25000 | K16: =MAX(I16-H16,0) -> 0 | L16: =IF(I16=0,"BELUM BAYAR",IF(I16<H16,"CICILAN",IF(I16>H16,"LUNAS (LEBIH)","LUNAS"))) -> BELUM BAYAR | M16: =IF(C16="","-",IF(C16=0,"BELUM BAYAR",IF(C16<$F$2,"CICILAN",IF(C16>$F$2,"LUNAS (LEBIH)","LUNAS")))) -> BELUM BAYAR | N16: =IF(D16="","-",IF(D16=0,"BELUM BAYAR",IF(D16<$F$2,"CICILAN",IF(D16>$F$2,"LUNAS (LEBIH)","LUNAS")))) -> BELUM BAYAR | O16: =IF(E16="","-",IF(E16=0,"BELUM BAYAR",IF(E16<$F$2,"CICILAN",IF(E16>$F$2,"LUNAS (LEBIH)","LUNAS")))) -> BELUM BAYAR | P16: =IF(F16="","-",IF(F16=0,"BELUM BAYAR",IF(F16<$F$2,"CICILAN",IF(F16>$F$2,"LUNAS (LEBIH)","LUNAS")))) -> BELUM BAYAR | Q16: =IF(G16="","-",IF(G16=0,"BELUM BAYAR",IF(G16<$F$2,"CICILAN",IF(G16>$F$2,"LUNAS (LEBIH)","LUNAS")))) -> BELUM BAYAR
... A45: =MASTER_ANGGOTA!A45 -> 41 | B45: =MASTER_ANGGOTA!B45 -> Nama Siswa 41 | C45: =IF(1<=$D$2,SUMIFS(PEMBAYARAN!$E$4:$E$500,PEMBAYARAN!$A$4:$A$500,$B45,PEMBAYARAN!$B$4:$B$500,"Oktober",PEMBAYARAN!$C$4:$C$500,"Minggu 1"),"") -> 0 | D45: =IF(2<=$D$2,SUMIFS(PEMBAYARAN!$E$4:$E$500,PEMBAYARAN!$A$4:$A$500,$B45,PEMBAYARAN!$B$4:$B$500,"Oktober",PEMBAYARAN!$C$4:$C$500,"Minggu 2"),"") -> 0 | E45: =IF(3<=$D$2,SUMIFS(PEMBAYARAN!$E$4:$E$500,PEMBAYARAN!$A$4:$A$500,$B45,PEMBAYARAN!$B$4:$B$500,"Oktober",PEMBAYARAN!$C$4:$C$500,"Minggu 3"),"") -> 0 | F45: =IF(4<=$D$2,SUMIFS(PEMBAYARAN!$E$4:$E$500,PEMBAYARAN!$A$4:$A$500,$B45,PEMBAYARAN!$B$4:$B$500,"Oktober",PEMBAYARAN!$C$4:$C$500,"Minggu 4"),"") -> 0 | G45: =IF(5<=$D$2,SUMIFS(PEMBAYARAN!$E$4:$E$500,PEMBAYARAN!$A$4:$A$500,$B45,PEMBAYARAN!$B$4:$B$500,"Oktober",PEMBAYARAN!$C$4:$C$500,"Minggu 5"),"") -> 0 | H45: =MIN($D$2,5)*$F$2 -> 25000 | I45: =SUM(C45:G45) -> 0 | J45: =MAX(H45-I45,0) -> 25000 | K45: =MAX(I45-H45,0) -> 0 | L45: =IF(I45=0,"BELUM BAYAR",IF(I45<H45,"CICILAN",IF(I45>H45,"LUNAS (LEBIH)","LUNAS"))) -> BELUM BAYAR | M45: =IF(C45="","-",IF(C45=0,"BELUM BAYAR",IF(C45<$F$2,"CICILAN",IF(C45>$F$2,"LUNAS (LEBIH)","LUNAS")))) -> BELUM BAYAR | N45: =IF(D45="","-",IF(D45=0,"BELUM BAYAR",IF(D45<$F$2,"CICILAN",IF(D45>$F$2,"LUNAS (LEBIH)","LUNAS")))) -> BELUM BAYAR | O45: =IF(E45="","-",IF(E45=0,"BELUM BAYAR",IF(E45<$F$2,"CICILAN",IF(E45>$F$2,"LUNAS (LEBIH)","LUNAS")))) -> BELUM BAYAR | P45: =IF(F45="","-",IF(F45=0,"BELUM BAYAR",IF(F45<$F$2,"CICILAN",IF(F45>$F$2,"LUNAS (LEBIH)","LUNAS")))) -> BELUM BAYAR | Q45: =IF(G45="","-",IF(G45=0,"BELUM BAYAR",IF(G45<$F$2,"CICILAN",IF(G45>$F$2,"LUNAS (LEBIH)","LUNAS")))) -> BELUM BAYAR
B47: TOTAL | H47: =SUM(H5:H45) -> 1025000 | I47: =SUM(I5:I45) -> 0 | J47: =SUM(J5:J45) -> 1025000 | K47: =SUM(K5:K45) -> 0
B48: Jumlah Anggota LUNAS: | D48: =COUNTIF(L5:L45,"LUNAS")+COUNTIF(L5:L45,"LUNAS (LEBIH)") -> 0
B49: Jumlah Anggota CICILAN: | D49: =COUNTIF(L5:L45,"CICILAN") -> 0
B50: Jumlah Anggota BELUM BAYAR: | D50: =COUNTIF(L5:L45,"BELUM BAYAR") -> 41

Sheet KAS_NOVEMBER
A1: REKAP KAS BULAN NOVEMBER 2026/2027
A2: Jumlah Minggu Aktif Bulan Ini: | D2: 4 | E2: Iuran / Minggu: | F2: 5000
A3: Kuning = sel input (boleh diedit) | Putih = hasil formula (otomatis)
A4: No | B4: Nama | C4: Minggu 1 | D4: Minggu 2 | E4: Minggu 3 | F4: Minggu 4 | G4: Minggu 5 | H4: Total Wajib | I4: Total Dibayar | J4: Kekurangan | K4: Kelebihan | L4: Status | M4: Status M1 | N4: Status M2 | O4: Status M3 | P4: Status M4 | Q4: Status M5
A5: =MASTER_ANGGOTA!A5 -> 1 | B5: =MASTER_ANGGOTA!B5 -> Budi | C5: =IF(1<=$D$2,SUMIFS(PEMBAYARAN!$E$4:$E$500,PEMBAYARAN!$A$4:$A$500,$B5,PEMBAYARAN!$B$4:$B$500,"November",PEMBAYARAN!$C$4:$C$500,"Minggu 1"),"") -> 0 | D5: =IF(2<=$D$2,SUMIFS(PEMBAYARAN!$E$4:$E$500,PEMBAYARAN!$A$4:$A$500,$B5,PEMBAYARAN!$B$4:$B$500,"November",PEMBAYARAN!$C$4:$C$500,"Minggu 2"),"") -> 0 | E5: =IF(3<=$D$2,SUMIFS(PEMBAYARAN!$E$4:$E$500,PEMBAYARAN!$A$4:$A$500,$B5,PEMBAYARAN!$B$4:$B$500,"November",PEMBAYARAN!$C$4:$C$500,"Minggu 3"),"") -> 0 | F5: =IF(4<=$D$2,SUMIFS(PEMBAYARAN!$E$4:$E$500,PEMBAYARAN!$A$4:$A$500,$B5,PEMBAYARAN!$B$4:$B$500,"November",PEMBAYARAN!$C$4:$C$500,"Minggu 4"),"") -> 0 | G5: =IF(5<=$D$2,SUMIFS(PEMBAYARAN!$E$4:$E$500,PEMBAYARAN!$A$4:$A$500,$B5,PEMBAYARAN!$B$4:$B$500,"November",PEMBAYARAN!$C$4:$C$500,"Minggu 5"),"") | H5: =MIN($D$2,5)*$F$2 -> 20000 | I5: =SUM(C5:G5) -> 0 | J5: =MAX(H5-I5,0) -> 20000 | K5: =MAX(I5-H5,0) -> 0 | L5: =IF(I5=0,"BELUM BAYAR",IF(I5<H5,"CICILAN",IF(I5>H5,"LUNAS (LEBIH)","LUNAS"))) -> BELUM BAYAR | M5: =IF(C5="","-",IF(C5=0,"BELUM BAYAR",IF(C5<$F$2,"CICILAN",IF(C5>$F$2,"LUNAS (LEBIH)","LUNAS")))) -> BELUM BAYAR | N5: =IF(D5="","-",IF(D5=0,"BELUM BAYAR",IF(D5<$F$2,"CICILAN",IF(D5>$F$2,"LUNAS (LEBIH)","LUNAS")))) -> BELUM BAYAR | O5: =IF(E5="","-",IF(E5=0,"BELUM BAYAR",IF(E5<$F$2,"CICILAN",IF(E5>$F$2,"LUNAS (LEBIH)","LUNAS")))) -> BELUM BAYAR | P5: =IF(F5="","-",IF(F5=0,"BELUM BAYAR",IF(F5<$F$2,"CICILAN",IF(F5>$F$2,"LUNAS (LEBIH)","LUNAS")))) -> BELUM BAYAR | Q5: =IF(G5="","-",IF(G5=0,"BELUM BAYAR",IF(G5<$F$2,"CICILAN",IF(G5>$F$2,"LUNAS (LEBIH)","LUNAS")))) -> -
A6: =MASTER_ANGGOTA!A6 -> 2 | B6: =MASTER_ANGGOTA!B6 -> Andi | C6: =IF(1<=$D$2,SUMIFS(PEMBAYARAN!$E$4:$E$500,PEMBAYARAN!$A$4:$A$500,$B6,PEMBAYARAN!$B$4:$B$500,"November",PEMBAYARAN!$C$4:$C$500,"Minggu 1"),"") -> 0 | D6: =IF(2<=$D$2,SUMIFS(PEMBAYARAN!$E$4:$E$500,PEMBAYARAN!$A$4:$A$500,$B6,PEMBAYARAN!$B$4:$B$500,"November",PEMBAYARAN!$C$4:$C$500,"Minggu 2"),"") -> 0 | E6: =IF(3<=$D$2,SUMIFS(PEMBAYARAN!$E$4:$E$500,PEMBAYARAN!$A$4:$A$500,$B6,PEMBAYARAN!$B$4:$B$500,"November",PEMBAYARAN!$C$4:$C$500,"Minggu 3"),"") -> 0 | F6: =IF(4<=$D$2,SUMIFS(PEMBAYARAN!$E$4:$E$500,PEMBAYARAN!$A$4:$A$500,$B6,PEMBAYARAN!$B$4:$B$500,"November",PEMBAYARAN!$C$4:$C$500,"Minggu 4"),"") -> 0 | G6: =IF(5<=$D$2,SUMIFS(PEMBAYARAN!$E$4:$E$500,PEMBAYARAN!$A$4:$A$500,$B6,PEMBAYARAN!$B$4:$B$500,"November",PEMBAYARAN!$C$4:$C$500,"Minggu 5"),"") | H6: =MIN($D$2,5)*$F$2 -> 20000 | I6: =SUM(C6:G6) -> 0 | J6: =MAX(H6-I6,0) -> 20000 | K6: =MAX(I6-H6,0) -> 0 | L6: =IF(I6=0,"BELUM BAYAR",IF(I6<H6,"CICILAN",IF(I6>H6,"LUNAS (LEBIH)","LUNAS"))) -> BELUM BAYAR | M6: =IF(C6="","-",IF(C6=0,"BELUM BAYAR",IF(C6<$F$2,"CICILAN",IF(C6>$F$2,"LUNAS (LEBIH)","LUNAS")))) -> BELUM BAYAR | N6: =IF(D6="","-",IF(D6=0,"BELUM BAYAR",IF(D6<$F$2,"CICILAN",IF(D6>$F$2,"LUNAS (LEBIH)","LUNAS")))) -> BELUM BAYAR | O6: =IF(E6="","-",IF(E6=0,"BELUM BAYAR",IF(E6<$F$2,"CICILAN",IF(E6>$F$2,"LUNAS (LEBIH)","LUNAS")))) -> BELUM BAYAR | P6: =IF(F6="","-",IF(F6=0,"BELUM BAYAR",IF(F6<$F$2,"CICILAN",IF(F6>$F$2,"LUNAS (LEBIH)","LUNAS")))) -> BELUM BAYAR | Q6: =IF(G6="","-",IF(G6=0,"BELUM BAYAR",IF(G6<$F$2,"CICILAN",IF(G6>$F$2,"LUNAS (LEBIH)","LUNAS")))) -> -
A7: =MASTER_ANGGOTA!A7 -> 3 | B7: =MASTER_ANGGOTA!B7 -> Citra | C7: =IF(1<=$D$2,SUMIFS(PEMBAYARAN!$E$4:$E$500,PEMBAYARAN!$A$4:$A$500,$B7,PEMBAYARAN!$B$4:$B$500,"November",PEMBAYARAN!$C$4:$C$500,"Minggu 1"),"") -> 0 | D7: =IF(2<=$D$2,SUMIFS(PEMBAYARAN!$E$4:$E$500,PEMBAYARAN!$A$4:$A$500,$B7,PEMBAYARAN!$B$4:$B$500,"November",PEMBAYARAN!$C$4:$C$500,"Minggu 2"),"") -> 0 | E7: =IF(3<=$D$2,SUMIFS(PEMBAYARAN!$E$4:$E$500,PEMBAYARAN!$A$4:$A$500,$B7,PEMBAYARAN!$B$4:$B$500,"November",PEMBAYARAN!$C$4:$C$500,"Minggu 3"),"") -> 0 | F7: =IF(4<=$D$2,SUMIFS(PEMBAYARAN!$E$4:$E$500,PEMBAYARAN!$A$4:$A$500,$B7,PEMBAYARAN!$B$4:$B$500,"November",PEMBAYARAN!$C$4:$C$500,"Minggu 4"),"") -> 0 | G7: =IF(5<=$D$2,SUMIFS(PEMBAYARAN!$E$4:$E$500,PEMBAYARAN!$A$4:$A$500,$B7,PEMBAYARAN!$B$4:$B$500,"November",PEMBAYARAN!$C$4:$C$500,"Minggu 5"),"") | H7: =MIN($D$2,5)*$F$2 -> 20000 | I7: =SUM(C7:G7) -> 0 | J7: =MAX(H7-I7,0) -> 20000 | K7: =MAX(I7-H7,0) -> 0 | L7: =IF(I7=0,"BELUM BAYAR",IF(I7<H7,"CICILAN",IF(I7>H7,"LUNAS (LEBIH)","LUNAS"))) -> BELUM BAYAR | M7: =IF(C7="","-",IF(C7=0,"BELUM BAYAR",IF(C7<$F$2,"CICILAN",IF(C7>$F$2,"LUNAS (LEBIH)","LUNAS")))) -> BELUM BAYAR | N7: =IF(D7="","-",IF(D7=0,"BELUM BAYAR",IF(D7<$F$2,"CICILAN",IF(D7>$F$2,"LUNAS (LEBIH)","LUNAS")))) -> BELUM BAYAR | O7: =IF(E7="","-",IF(E7=0,"BELUM BAYAR",IF(E7<$F$2,"CICILAN",IF(E7>$F$2,"LUNAS (LEBIH)","LUNAS")))) -> BELUM BAYAR | P7: =IF(F7="","-",IF(F7=0,"BELUM BAYAR",IF(F7<$F$2,"CICILAN",IF(F7>$F$2,"LUNAS (LEBIH)","LUNAS")))) -> BELUM BAYAR | Q7: =IF(G7="","-",IF(G7=0,"BELUM BAYAR",IF(G7<$F$2,"CICILAN",IF(G7>$F$2,"LUNAS (LEBIH)","LUNAS")))) -> -
A8: =MASTER_ANGGOTA!A8 -> 4 | B8: =MASTER_ANGGOTA!B8 -> Doni | C8: =IF(1<=$D$2,SUMIFS(PEMBAYARAN!$E$4:$E$500,PEMBAYARAN!$A$4:$A$500,$B8,PEMBAYARAN!$B$4:$B$500,"November",PEMBAYARAN!$C$4:$C$500,"Minggu 1"),"") -> 0 | D8: =IF(2<=$D$2,SUMIFS(PEMBAYARAN!$E$4:$E$500,PEMBAYARAN!$A$4:$A$500,$B8,PEMBAYARAN!$B$4:$B$500,"November",PEMBAYARAN!$C$4:$C$500,"Minggu 2"),"") -> 0 | E8: =IF(3<=$D$2,SUMIFS(PEMBAYARAN!$E$4:$E$500,PEMBAYARAN!$A$4:$A$500,$B8,PEMBAYARAN!$B$4:$B$500,"November",PEMBAYARAN!$C$4:$C$500,"Minggu 3"),"") -> 0 | F8: =IF(4<=$D$2,SUMIFS(PEMBAYARAN!$E$4:$E$500,PEMBAYARAN!$A$4:$A$500,$B8,PEMBAYARAN!$B$4:$B$500,"November",PEMBAYARAN!$C$4:$C$500,"Minggu 4"),"") -> 0 | G8: =IF(5<=$D$2,SUMIFS(PEMBAYARAN!$E$4:$E$500,PEMBAYARAN!$A$4:$A$500,$B8,PEMBAYARAN!$B$4:$B$500,"November",PEMBAYARAN!$C$4:$C$500,"Minggu 5"),"") | H8: =MIN($D$2,5)*$F$2 -> 20000 | I8: =SUM(C8:G8) -> 0 | J8: =MAX(H8-I8,0) -> 20000 | K8: =MAX(I8-H8,0) -> 0 | L8: =IF(I8=0,"BELUM BAYAR",IF(I8<H8,"CICILAN",IF(I8>H8,"LUNAS (LEBIH)","LUNAS"))) -> BELUM BAYAR | M8: =IF(C8="","-",IF(C8=0,"BELUM BAYAR",IF(C8<$F$2,"CICILAN",IF(C8>$F$2,"LUNAS (LEBIH)","LUNAS")))) -> BELUM BAYAR | N8: =IF(D8="","-",IF(D8=0,"BELUM BAYAR",IF(D8<$F$2,"CICILAN",IF(D8>$F$2,"LUNAS (LEBIH)","LUNAS")))) -> BELUM BAYAR | O8: =IF(E8="","-",IF(E8=0,"BELUM BAYAR",IF(E8<$F$2,"CICILAN",IF(E8>$F$2,"LUNAS (LEBIH)","LUNAS")))) -> BELUM BAYAR | P8: =IF(F8="","-",IF(F8=0,"BELUM BAYAR",IF(F8<$F$2,"CICILAN",IF(F8>$F$2,"LUNAS (LEBIH)","LUNAS")))) -> BELUM BAYAR | Q8: =IF(G8="","-",IF(G8=0,"BELUM BAYAR",IF(G8<$F$2,"CICILAN",IF(G8>$F$2,"LUNAS (LEBIH)","LUNAS")))) -> -
A9: =MASTER_ANGGOTA!A9 -> 5 | B9: =MASTER_ANGGOTA!B9 -> Nama Siswa 5 | C9: =IF(1<=$D$2,SUMIFS(PEMBAYARAN!$E$4:$E$500,PEMBAYARAN!$A$4:$A$500,$B9,PEMBAYARAN!$B$4:$B$500,"November",PEMBAYARAN!$C$4:$C$500,"Minggu 1"),"") -> 0 | D9: =IF(2<=$D$2,SUMIFS(PEMBAYARAN!$E$4:$E$500,PEMBAYARAN!$A$4:$A$500,$B9,PEMBAYARAN!$B$4:$B$500,"November",PEMBAYARAN!$C$4:$C$500,"Minggu 2"),"") -> 0 | E9: =IF(3<=$D$2,SUMIFS(PEMBAYARAN!$E$4:$E$500,PEMBAYARAN!$A$4:$A$500,$B9,PEMBAYARAN!$B$4:$B$500,"November",PEMBAYARAN!$C$4:$C$500,"Minggu 3"),"") -> 0 | F9: =IF(4<=$D$2,SUMIFS(PEMBAYARAN!$E$4:$E$500,PEMBAYARAN!$A$4:$A$500,$B9,PEMBAYARAN!$B$4:$B$500,"November",PEMBAYARAN!$C$4:$C$500,"Minggu 4"),"") -> 0 | G9: =IF(5<=$D$2,SUMIFS(PEMBAYARAN!$E$4:$E$500,PEMBAYARAN!$A$4:$A$500,$B9,PEMBAYARAN!$B$4:$B$500,"November",PEMBAYARAN!$C$4:$C$500,"Minggu 5"),"") | H9: =MIN($D$2,5)*$F$2 -> 20000 | I9: =SUM(C9:G9) -> 0 | J9: =MAX(H9-I9,0) -> 20000 | K9: =MAX(I9-H9,0) -> 0 | L9: =IF(I9=0,"BELUM BAYAR",IF(I9<H9,"CICILAN",IF(I9>H9,"LUNAS (LEBIH)","LUNAS"))) -> BELUM BAYAR | M9: =IF(C9="","-",IF(C9=0,"BELUM BAYAR",IF(C9<$F$2,"CICILAN",IF(C9>$F$2,"LUNAS (LEBIH)","LUNAS")))) -> BELUM BAYAR | N9: =IF(D9="","-",IF(D9=0,"BELUM BAYAR",IF(D9<$F$2,"CICILAN",IF(D9>$F$2,"LUNAS (LEBIH)","LUNAS")))) -> BELUM BAYAR | O9: =IF(E9="","-",IF(E9=0,"BELUM BAYAR",IF(E9<$F$2,"CICILAN",IF(E9>$F$2,"LUNAS (LEBIH)","LUNAS")))) -> BELUM BAYAR | P9: =IF(F9="","-",IF(F9=0,"BELUM BAYAR",IF(F9<$F$2,"CICILAN",IF(F9>$F$2,"LUNAS (LEBIH)","LUNAS")))) -> BELUM BAYAR | Q9: =IF(G9="","-",IF(G9=0,"BELUM BAYAR",IF(G9<$F$2,"CICILAN",IF(G9>$F$2,"LUNAS (LEBIH)","LUNAS")))) -> -
